Workbook

Sheet Sheet1
B1: 桩号m | D1: 地面线 | E1: 地面 | F1: 比降 | G1: 渠底 | N1: 修正
B2: K0+000 | C2: 0 | D2: 1730.257 | E2: =ROUND(D2,2) -> 1730.26 | F2: ="1/"&ROUND(1/K2,0) -> 1/100 | G2: 1729.87 | H2: 1729.87 | I2: =G2-H2 -> 0 | J2: =E2-G2 -> 0.39 | K2: 0.01
B3: K0+010 | C3: 10 | D3: 1730.023 | E3: =ROUND(D3,2) -> 1730.02 | F3: ="1/"&ROUND(1/K3,0) -> 1/100 | G3: =E2-K2*(C3-C2) -> 1730.16 | H3: 1730.16 | I3: =G3-H3 -> 0 | J3: =E3-G3 -> -0.14 | K3: 0.01
B4: K0+013 | C4: 13 | D4: 1730 | E4: =ROUND(D4,2) -> 1730 | F4: ="1/"&ROUND(1/K4,0) -> 1/100 | G4: =E3-K3*(C4-C3) -> 1729.99 | H4: 1729.99 | I4: =G4-H4 -> 0 | J4: =E4-G4 -> 0.01 | K4: 0.01
B5: K0+020 | C5: 20 | D5: 1729.712 | E5: =ROUND(D5,2) -> 1729.71 | F5: ="1/"&ROUND(1/K5,0) -> 1/100 | G5: =E4-K4*(C5-C4) -> 1729.93 | H5: 1729.93 | I5: =G5-H5 -> 0 | J5: =E5-G5 -> -0.22 | K5: 0.01
A6: 接消力池 | B6: K0+030 | C6: 30 | D6: 1729.583 | E6: =ROUND(D6,2) -> 1729.58 | F6: ="1/"&ROUND(1/K6,0) -> 1/500 | G6: 1728 | H6: 1728 | I6: =G6-H6 -> 0 | J6: =E6-G6 -> 1.58 | K6: 0.002 | L6: 1728.08
B7: K0+040 | C7: 40 | D7: 1729.301 | E7: =ROUND(D7,2) -> 1729.3 | F7: ="1/"&ROUND(1/K7,0) -> 1/500 | G7: =ROUND(G6-(C7-C6)*K6,2) -> 1727.98 | H7: 1727.98 | I7: =G7-H7 -> 0 | J7: =E7-G7 -> 1.32 | K7: 0.002 | L7: 1728.06
B8: K0+050 | C8: 50 | D8: 1728.903 | E8: =ROUND(D8,2) -> 1728.9 | F8: ="1/"&ROUND(1/K8,0) -> 1/500 | G8: =ROUND(G7-(C8-C7)*K7,2) -> 1727.96 | H8: 1727.96 | I8: =G8-H8 -> 0 | J8: =E8-G8 -> 0.94 | K8: 0.002 | L8: 1728.04
B9: K0+100 | C9: 100 | D9: 1729.728 | E9: =ROUND(D9,2) -> 1729.73 | F9: ="1/"&ROUND(1/K9,0) -> 1/500 | G9: =ROUND(G8-(C9-C8)*K8,2) -> 1727.86 | H9: 1727.86 | I9: =G9-H9 -> 0 | J9: =E9-G9 -> 1.87 | K9: 0.002 | L9: 1727.94
B10: K0+150 | C10: 150 | D10: 1728.713 | E10: =ROUND(D10,2) -> 1728.71 | F10: ="1/"&ROUND(1/K10,0) -> 1/500 | G10: =ROUND(G9-(C10-C9)*K9,2) -> 1727.76 | H10: 1727.76 | I10: =G10-H10 -> 0 | J10: =E10-G10 -> 0.95 | K10: 0.002 | L10: 1727.84
B11: K0+200 | C11: 200 | D11: 1727.885 | E11: =ROUND(D11,2) -> 1727.89 | F11: ="1/"&ROUND(1/K11,0) -> 1/500 | G11: =ROUND(G10-(C11-C10)*K10,2) -> 1727.66 | H11: 1727.66 | I11: =G11-H11 -> 0 | J11: =E11-G11 -> 0.23 | K11: 0.002 | L11: 1727.74
A12: 跌水2.2 | B12: K0+210 | C12: 210 | D12: 1727.727 | E12: =ROUND(D12,2) -> 1727.73 | F12: ="1/"&ROUND(1/K12,0) -> 1/500 | G12: =ROUND(G11-(C12-C11)*K11,2) -> 1727.64 | H12: 1727.64 | I12: =G12-H12 -> 0 | J12: =E12-G12 -> 0.09 | K12: 0.002 | L12: 1727.72
C13: 213 | D13: 1727.727 | E13: =ROUND(D13,2) -> 1727.73 | G13: =G12-2.2 -> 1725.44 | H13: 1725.44 | I13: =G13-H13 -> 0 | J13: =E13-G13 -> 2.29 | K13: 0.002 | L13: 1725.81
C14: 250 | D14: =D12-0.014*(C14-C12) -> 1727.167 | E14: =ROUND(D14,2) -> 1727.17 | F14: ="1/"&ROUND(1/K14,0) -> 1/500 | G14: =ROUND(G13-(C14-C13+1)*K13,2) -> 1725.36 | H14: 1725.36 | I14: =G14-H14 -> 0 | J14: =E14-G14 -> 1.81 | K14: 0.002 | L14: 1725.73 | M14: =D12-D22 -> 3.697 | N14: =C22-C12 -> 254
C15: 300 | D15: =D13-0.014*(C15-C13) -> 1726.509 | E15: =ROUND(D15,2) -> 1726.51 | F15: ="1/"&ROUND(1/K15,0) -> 1/500 | G15: =ROUND(G14-(C15-C14)*K14,2) -> 1725.26 | H15: 1725.26 | I15: =G15-H15 -> 0 | J15: =E15-G15 -> 1.25 | K15: 0.002 | L15: 1725.56 | M15: =M14/N14 -> 0.014555118
C16: 350 | D16: =D14-0.014*(C16-C14) -> 1725.767 | E16: =ROUND(D16,2) -> 1725.77 | F16: ="1/"&ROUND(1/K16,0) -> 1/500 | G16: =ROUND(G15-(C16-C15)*K15,2) -> 1725.16 | H16: 1725.16 | I16: =G16-H16 -> 0 | J16: =E16-G16 -> 0.61 | K16: 0.002 | L16: 1725.36
C17: 400 | D17: =D15-0.014*(C17-C15) -> 1725.109 | E17: =ROUND(D17,2) -> 1725.11 | F17: ="1/"&ROUND(1/K17,0) -> 1/500 | G17: =ROUND(G16-(C17-C16)*K16,2) -> 1725.06 | H17: 1725.06 | I17: =G17-H17 -> 0 | J17: =E17-G17 -> 0.05 | K17: 0.002 | L17: 1725.16
A18: 跌水2.2 | C18: 420 | D18: =D16-0.014*(C18-C16) -> 1724.787 | E18: =ROUND(D18,2) -> 1724.79 | G18: =ROUND(G17-(C18-C17)*K17,2) -> 1725.02 | H18: 1725.02 | I18: =G18-H18 -> 0 | J18: =E18-G18 -> -0.23 | K18: 0.002 | L18: 1725.02
C19: 423 | D19: =D17-0.014*(C19-C17) -> 1724.787 | E19: =ROUND(D19,2) -> 1724.79 | G19: =G18-2.2 -> 1722.82 | H19: 1725.02 | I19: =G19-H19 -> -2.2 | J19: =E19-G19 -> 1.97 | K19: 0.002 | L19: 1722.81
C20: 430 | D20: =D16-0.014*(C20-C16) -> 1724.647 | E20: =ROUND(D20,2) -> 1724.65 | F20: ="1/"&ROUND(1/K20,0) -> 1/500 | G20: =ROUND(G19-(C20-C19-5)*K19,2) -> 1722.82 | H20: 1722.82 | I20: =G20-H20 -> 0 | J20: =E20-G20 -> 1.83 | K20: 0.002 | L20: 1722.8
B21: K0+460 | C21: 460 | D21: =D17-0.014*(C21-C17) -> 1724.269 | E21: =ROUND(D21,2) -> 1724.27 | F21: ="1/"&ROUND(1/K21,0) -> 1/500 | G21: =ROUND(G20-(C21-C20)*K20,2) -> 1722.76 | H21: 1722.76 | I21: =G21-H21 -> 0 | J21: =E21-G21 -> 1.51 | K21: 0.002 | L21: 1722.74
B22: K0+464 | C22: 464 | D22: 1724.03 | E22: =ROUND(D22,2) -> 1724.03 | F22: ="1/"&ROUND(1/K22,0) -> 1/500 | G22: =ROUND(G21-(C22-C21)*K21,2) -> 1722.75 | H22: 1722.75 | I22: =G22-H22 -> 0 | J22: =E22-G22 -> 1.28 | K22: 0.002 | L22: 1722.73
B23: K0+500 | C23: 500 | D23: 1723.459 | E23: =ROUND(D23,2) -> 1723.46 | F23: ="1/"&ROUND(1/K23,0) -> 1/500 | G23: =ROUND(G22-(C23-C22)*K22,2) -> 1722.68 | H23: 1722.68 | I23: =G23-H23 -> 0 | J23: =E23-G23 -> 0.78 | K23: 0.002 | L23: 1722.66
B24: K0+550 | C24: 550 | D24: 1722.885 | E24: =ROUND(D24,2) -> 1722.89 | F24: ="1/"&ROUND(1/K24,0) -> 1/500 | G24: =ROUND(G23-(C24-C23)*K23,2) -> 1722.58 | H24: 1722.58 | I24: =G24-H24 -> 0 | J24: =E24-G24 -> 0.31 | K24: 0.002 | L24: 1722.56
B25: K0+600 | C25: 600 | D25: 1722.379 | E25: =ROUND(D25,2) -> 1722.38 | F25: ="1/"&ROUND(1/K25,0) -> 1/500 | G25: =ROUND(G24-(C25-C24)*K24,2) -> 1722.48 | H25: 1722.48 | I25: =G25-H25 -> 0 | J25: =E25-G25 -> -0.1 | K25: 0.002 | L25: 1722.46
B26: K0+610 | C26: 610 | D26: 1722.623 | E26: =ROUND(D26,2) -> 1722.62 | F26: ="1/"&ROUND(1/K26,0) -> 1/500 | G26: =ROUND(G25-(C26-C25)*K25,2) -> 1722.46 | H26: 1722.46 | I26: =G26-H26 -> 0 | J26: =E26-G26 -> 0.16 | K26: 0.002 | L26: 1722.44 | M26: =E26-E31 -> 1.01 | N26: =C31-C26 -> 100
C27: 650 | E27: =E26-(C27-C26)*0.01 -> 1722.22 | G27: =ROUND(G26-(C27-C26)*K26,2) -> 1722.38 | H27: 1722.38 | I27: =G27-H27 -> 0 | J27: =E27-G27 -> -0.16 | K27: 0.002 | L27: 1722.36 | M27: =M26/N26 -> 0.0101
A28: 跌水2.2 | C28: 660 | E28: =E27-(C28-C27)*0.01 -> 1722.12 | G28: =ROUND(G27-(C28-C27)*K27,2) -> 1722.36 | H28: 1722.36 | I28: =G28-H28 -> 0 | J28: =E28-G28 -> -0.24 | K28: 0.002 | L28: 1722.34
C29: 663 | E29: =E28-(C29-C28)*0.01 -> 1722.09 | G29: =G28-2.2 -> 1720.16 | H29: 1720.16 | I29: =G29-H29 -> 0 | J29: =E29-G29 -> 1.93 | K29: 0.002
C30: 700 | E30: =E29-(C30-C29)*0.01 -> 1721.72 | G30: =ROUND(G29-(C30-C29+1)*K29,2) -> 1720.08 | H30: 1720.08 | I30: =G30-H30 -> 0 | J30: =E30-G30 -> 1.64 | K30: 0.002
B31: K0+710 | C31: 710 | D31: 1721.611 | E31: =ROUND(D31,2) -> 1721.61 | F31: ="1/"&ROUND(1/K31,0) -> 1/500 | G31: =ROUND(G30-(C31-C30)*K30,2) -> 1720.06 | H31: 1720.06 | I31: =G31-H31 -> 0 | J31: =E31-G31 -> 1.55 | K31: 0.002
B32: K0+750 | C32: 750 | D32: 1721.195 | E32: =ROUND(D32,2) -> 1721.2 | F32: ="1/"&ROUND(1/K32,0) -> 1/500 | G32: =ROUND(G31-(C32-C31)*K31,2) -> 1719.98 | H32: 1719.98 | I32: =G32-H32 -> 0 | J32: =E32-G32 -> 1.22 | K32: 0.002
B33: K0+800 | C33: 800 | D33: 1720.597 | E33: =ROUND(D33,2) -> 1720.6 | F33: ="1/"&ROUND(1/K33,0) -> 1/500 | G33: =ROUND(G32-(C33-C32)*K32,2) -> 1719.88 | H33: 1719.88 | I33: =G33-H33 -> 0 | J33: =E33-G33 -> 0.72 | K33: 0.002
B34: K0+850 | C34: 850 | D34: 1720 | E34: =ROUND(D34,2) -> 1720 | F34: ="1/"&ROUND(1/K34,0) -> 1/500 | G34: =ROUND(G33-(C34-C33)*K33,2) -> 1719.78 | H34: 1719.78 | I34: =G34-H34 -> 0 | J34: =E34-G34 -> 0.22 | K34: 0.002
A35: 跌水2.2 | B35: K0+880 | C35: 880 | D35: 1719.501 | E35: =ROUND(D35,2) -> 1719.5 | F35: ="1/"&ROUND(1/K35,0) -> 1/500 | G35: =ROUND(G34-(C35-C34)*K34,2) -> 1719.72 | H35: 1719.72 | I35: =G35-H35 -> 0 | J35: =E35-G35 -> -0.22 | K35: 0.002
C36: 882 | D36: 1719.501 | E36: 1719.49 | G36: =G35-2.2 -> 1717.52 | H36: 1717.52 | I36: =G36-H36 -> 0 | J36: =E36-G36 -> 1.97 | K36: 0.002
C37: 900 | E37: =E36-(C37-C36)*0.012 -> 1719.274 | G37: =ROUND(G36-(C37-C36)*K36,2) -> 1717.48 | H37: 1717.48 | I37: =G37-H37 -> 0 | J37: =E37-G37 -> 1.794 | K37: 0.002 | M37: =E36-E38 -> 0.7 | N37: =C38-C36 -> 58
B38: K0+940 | C38: 940 | D38: 1718.793 | E38: =ROUND(D38,2) -> 1718.79 | F38: ="1/"&ROUND(1/K38,0) -> 1/500 | G38: =ROUND(G37-(C38-C37)*K37,2) -> 1717.4 | H38: 1717.4 | I38: =G38-H38 -> 0 | J38: =E38-G38 -> 1.39 | K38: 0.002 | M38: =M37/N37 -> 0.012068966
B39: K0+950 | C39: 950 | D39: 1718.597 | E39: =ROUND(D39,2) -> 1718.6 | F39: ="1/"&ROUND(1/K39,0) -> 1/500 | G39: =ROUND(G38-(C39-C38)*K38,2) -> 1717.38 | H39: 1717.38 | I39: =G39-H39 -> 0 | J39: =E39-G39 -> 1.22 | K39: 0.002
B40: K1+000 | C40: 1000 | D40: 1717.904 | E40: =ROUND(D40,2) -> 1717.9 | F40: ="1/"&ROUND(1/K40,0) -> 1/500 | G40: =ROUND(G39-(C40-C39)*K39,2) -> 1717.28 | H40: 1717.28 | I40: =G40-H40 -> 0 | J40: =E40-G40 -> 0.62 | K40: 0.002
...

Sheet Sheet2
B1: 桩号m | D1: 地面线 | E1: 地面 | F1: 比降 | G1: 渠底
B2: K0+000 | C2: 0 | D2: 1730.257 | E2: =ROUND(D2,2) -> 1730.26 | F2: ="1/"&ROUND(1/K2,0) -> 1/100 | G2: 1729.87 | H2: 1729.87 | I2: =G2-H2 -> 0 | J2: =E2-G2 -> 0.39 | K2: 0.01
B3: K0+010 | C3: 10 | D3: 1730.023 | E3: =ROUND(D3,2) -> 1730.02 | F3: ="1/"&ROUND(1/K3,0) -> 1/100 | G3: =E2-K2*(C3-C2) -> 1730.16 | H3: 1730.16 | I3: =G3-H3 -> 0 | J3: =E3-G3 -> -0.14 | K3: 0.01
B4: K0+013 | C4: 13 | D4: 1730 | E4: =ROUND(D4,2) -> 1730 | F4: ="1/"&ROUND(1/K4,0) -> 1/100 | G4: =E3-K3*(C4-C3) -> 1729.99 | H4: 1729.99 | I4: =G4-H4 -> 0 | J4: =E4-G4 -> 0.01 | K4: 0.01
B5: K0+020 | C5: 20 | D5: 1729.712 | E5: =ROUND(D5,2) -> 1729.71 | F5: ="1/"&ROUND(1/K5,0) -> 1/100 | G5: =E4-K4*(C5-C4) -> 1729.93 | H5: 1729.93 | I5: =G5-H5 -> 0 | J5: =E5-G5 -> -0.22 | K5: 0.01
B6: K0+030 | C6: 30 | D6: 1729.583 | E6: =ROUND(D6,2) -> 1729.58 | F6: ="1/"&ROUND(1/K6,0) -> 1/100 | G6: 1728 | H6: 1728 | I6: =G6-H6 -> 0 | J6: =E6-G6 -> 1.58 | K6: 0.01 | L6: 1728.08
B7: K0+040 | C7: 40 | D7: 1729.301 | E7: =ROUND(D7,2) -> 1729.3 | F7: ="1/"&ROUND(1/K7,0) -> 1/100 | G7: =ROUND(G6-(C7-C6)*K6,2) -> 1727.9 | H7: 1727.98 | I7: =G7-H7 -> -0.08 | J7: =E7-G7 -> 1.4 | K7: 0.01 | L7: 1728.06
B8: K0+050 | C8: 50 | D8: 1728.903 | E8: =ROUND(D8,2) -> 1728.9 | F8: ="1/"&ROUND(1/K8,0) -> 1/100 | G8: =ROUND(G7-(C8-C7)*K7,2) -> 1727.8 | H8: 1727.96 | I8: =G8-H8 -> -0.16 | J8: =E8-G8 -> 1.1 | K8: 0.01 | L8: 1728.04
B9: K0+100 | C9: 100 | D9: 1729.728 | E9: =ROUND(D9,2) -> 1729.73 | F9: ="1/"&ROUND(1/K9,0) -> 1/100 | G9: =ROUND(G8-(C9-C8)*K8,2) -> 1727.3 | H9: 1727.86 | I9: =G9-H9 -> -0.56 | J9: =E9-G9 -> 2.43 | K9: 0.01 | L9: 1727.94
B10: K0+150 | C10: 150 | D10: 1728.713 | E10: =ROUND(D10,2) -> 1728.71 | F10: ="1/"&ROUND(1/K10,0) -> 1/100 | G10: =ROUND(G9-(C10-C9)*K9,2) -> 1726.8 | H10: 1727.76 | I10: =G10-H10 -> -0.96 | J10: =E10-G10 -> 1.91 | K10: 0.01 | L10: 1727.84
B11: K0+200 | C11: 200 | D11: 1727.885 | E11: =ROUND(D11,2) -> 1727.89 | F11: ="1/"&ROUND(1/K11,0) -> 1/100 | G11: =ROUND(G10-(C11-C10)*K10,2) -> 1726.3 | H11: 1727.66 | I11: =G11-H11 -> -1.36 | J11: =E11-G11 -> 1.59 | K11: 0.01 | L11: 1727.74
B12: K0+210 | C12: 210 | D12: 1727.727 | E12: =ROUND(D12,2) -> 1727.73 | F12: ="1/"&ROUND(1/K12,0) -> 1/100 | G12: =ROUND(G11-(C12-C11)*K11,2) -> 1726.2 | H12: 1727.64 | I12: =G12-H12 -> -1.44 | J12: =E12-G12 -> 1.53 | K12: 0.01 | L12: 1727.72
C13: 250 | D13: =D11-0.014*(C13-C11) -> 1727.185 | E13: =ROUND(D13,2) -> 1727.19 | F13: ="1/"&ROUND(1/K13,0) -> 1/100 | G13: =ROUND(G11-(C13-C11)*K11,2) -> 1725.8 | H13: 1727.56 | I13: =G13-H13 -> -1.76 | J13: =E13-G13 -> 1.39 | K13: 0.01 | L13: 1725.73 | M13: =D11-D22 -> 4.426
C14: 300 | D14: =D11-0.014*(C14-C11) -> 1726.485 | E14: =ROUND(D14,2) -> 1726.49 | F14: ="1/"&ROUND(1/K14,0) -> 1/100 | G14: =ROUND(G13-(C14-C13)*K13,2) -> 1725.3 | H14: 1727.46 | I14: =G14-H14 -> -2.16 | J14: =E14-G14 -> 1.19 | K14: 0.01 | L14: 1725.56
C15: 350 | D15: =D13-0.014*(C15-C13) -> 1725.785 | E15: =ROUND(D15,2) -> 1725.79 | F15: ="1/"&ROUND(1/K15,0) -> 1/100 | G15: =ROUND(G14-(C15-C14)*K14,2) -> 1724.8 | H15: 1727.36 | I15: =G15-H15 -> -2.56 | J15: =E15-G15 -> 0.99 | K15: 0.01 | L15: 1725.36
C16: 400 | D16: =D14-0.014*(C16-C14) -> 1725.085 | E16: =ROUND(D16,2) -> 1725.09 | F16: ="1/"&ROUND(1/K16,0) -> 1/100 | G16: =ROUND(G15-(C16-C15)*K15,2) -> 1724.3 | H16: 1727.26 | I16: =G16-H16 -> -2.96 | J16: =E16-G16 -> 0.79 | K16: 0.01 | L16: 1725.16
C17: 420 | D17: =D15-0.014*(C17-C15) -> 1724.805 | E17: =ROUND(D17,2) -> 1724.81 | G17: =ROUND(G16-(C17-C16)*K16,2) -> 1724.1 | H17: 1727.22 | I17: =G17-H17 -> -3.12 | J17: =E17-G17 -> 0.71 | K17: 0.01 | L17: 1725.02
C18: 423 | D18: =D16-0.014*(C18-C16) -> 1724.763 | E18: =ROUND(D18,2) -> 1724.76 | G18: =G17-2.2 -> 1721.9 | H18: 1725.02 | I18: =G18-H18 -> -3.12 | J18: =E18-G18 -> 2.86 | K18: 0.01 | L18: 1722.81
C19: 430 | D19: =D15-0.014*(C19-C15) -> 1724.665 | E19: =ROUND(D19,2) -> 1724.67 | F19: ="1/"&ROUND(1/K19,0) -> 1/100 | G19: =ROUND(G18-(C19-C18-5)*K18,2) -> 1721.88 | H19: 1725.02 | I19: =G19-H19 -> -3.14 | J19: =E19-G19 -> 2.79 | K19: 0.01 | L19: 1722.8
B20: K0+460 | C20: 460 | D20: =D16-0.014*(C20-C16) -> 1724.245 | E20: =ROUND(D20,2) -> 1724.25 | F20: ="1/"&ROUND(1/K20,0) -> 1/100 | G20: =ROUND(G19-(C20-C19)*K19,2) -> 1721.58 | H20: 1724.96 | I20: =G20-H20 -> -3.38 | J20: =E20-G20 -> 2.67 | K20: 0.01 | L20: 1722.74
B21: K0+464 | C21: 464 | D21: 1724.03 | E21: =ROUND(D21,2) -> 1724.03 | F21: ="1/"&ROUND(1/K21,0) -> 1/100 | G21: =ROUND(G20-(C21-C20)*K20,2) -> 1721.54 | H21: 1724.95 | I21: =G21-H21 -> -3.41 | J21: =E21-G21 -> 2.49 | K21: 0.01 | L21: 1722.73
B22: K0+500 | C22: 500 | D22: 1723.459 | E22: =ROUND(D22,2) -> 1723.46 | F22: ="1/"&ROUND(1/K22,0) -> 1/100 | G22: =ROUND(G21-(C22-C21)*K21,2) -> 1721.18 | H22: 1724.88 | I22: =G22-H22 -> -3.7 | J22: =E22-G22 -> 2.28 | K22: 0.01 | L22: 1722.66
B23: K0+550 | C23: 550 | D23: 1722.885 | E23: =ROUND(D23,2) -> 1722.89 | F23: ="1/"&ROUND(1/K23,0) -> 1/100 | G23: =ROUND(G22-(C23-C22)*K22,2) -> 1720.68 | H23: 1724.78 | I23: =G23-H23 -> -4.1 | J23: =E23-G23 -> 2.21 | K23: 0.01 | L23: 1722.56
B24: K0+600 | C24: 600 | D24: 1722.379 | E24: =ROUND(D24,2) -> 1722.38 | F24: ="1/"&ROUND(1/K24,0) -> 1/100 | G24: =ROUND(G23-(C24-C23)*K23,2) -> 1720.18 | H24: 1724.68 | I24: =G24-H24 -> -4.5 | J24: =E24-G24 -> 2.2 | K24: 0.01 | L24: 1722.46

Sheet 建筑物统计
A1: 渠道 | B1: 长度（km） | C1: 干渠引水闸 | D1: 分水闸 | E1: 箱涵 | F1: 跌水 | G1: 农桥 | H1: 斗口
A2: 干渠 | B2: =干渠!C405 -> 13283 | C2: 1 | D2: 12 | E2: 4 | F2: 22 | I2: =SUM(C2:H2) -> 39
A3: 1-1支渠 | B3: =支渠!E35 -> 6803 | D3: 15 | E3: 1 | G3: 3 | I3: =SUM(C3:H3) -> 19
A4: 1-2支渠 | B4: =支渠!E36 -> 7224 | D4: 13 | G4: 2 | I4: =SUM(C4:H4) -> 15 | K4: =39+120+107+97+81+38+146+65+66+54+57+44+69+64 -> 1047
A5: 1-3支渠 | B5: =支渠!E37 -> 4900 | D5: 15 | G5: 2 | I5: =SUM(C5:H5) -> 17
A6: 1-4支渠 | B6: =支渠!E38 -> 5310 | D6: 12 | F6: 1 | G6: 2 | I6: =SUM(C6:H6) -> 15
A7: 1-5支渠 | B7: =支渠!E39 -> 2545 | D7: 6 | G7: 1 | I7: =SUM(C7:H7) -> 7
A8: 2-1支渠 | B8: =支渠!E40 -> 4150 | D8: 22 | E8: 1 | G8: 17 | I8: =SUM(C8:H8) -> 40
A9: 2-2支渠 | B9: =支渠!E41 -> 4800 | D9: 12 | E9: 2 | G9: 3 | I9: =SUM(C9:H9) -> 17
A10: 2-3支渠 | B10: =支渠!E42 -> 4400 | D10: 11 | E10: 1 | G10: 14 | I10: =SUM(C10:H10) -> 26
A11: 2-4支渠 | B11: =支渠!E43 -> 4000 | D11: 10 | E11: 1 | G11: 3 | I11: =SUM(C11:H11) -> 14
A12: 2-5支渠 | B12: =支渠!E44 -> 3550 | D12: 9 | E12: 1 | G12: 10 | I12: =SUM(C12:H12) -> 20
A13: 2-6支渠 | B13: =支渠!E45 -> 3400 | D13: 8 | E13: 1 | G13: 2 | I13: =SUM(C13:H13) -> 11
A14: 2-7支渠 | B14: =支渠!E46 -> 5020 | D14: 11 | E14: 1 | G14: 7 | I14: =SUM(C14:H14) -> 19
B15: =SUM(B3:B14) -> 56102 | C15: =SUM(C3:C14) -> 0 | D15: =SUM(D3:D14) -> 144 | E15: =SUM(E3:E14) -> 9 | F15: =SUM(F3:F14) -> 1 | G15: =SUM(G3:G14) -> 66 | H15: =SUM(H3:H14) -> 0 | I15: =SUM(I3:I14) -> 220
A16: 斗渠 | B16: =斗渠!C176 -> 152691 | E16: 13 | G16: 51 | H16: 668 | I16: =SUM(C16:H16) -> 732
A17: 合计 | B17: =SUM(B2:B16) -> 278178 | C17: =C15+C16 -> 0 | D17: =D15+D16 -> 144 | E17: =E15+E16 -> 22 | F17: =F15+F16 -> 1 | G17: =G15+G16 -> 117 | H17: =H15+H16 -> 668 | I17: =SUM(C17:H17) -> 952 | J17: =SUM(I2:I16) -> 1211
G19: =117-G17 -> 0
A22: 渠道 | B22: 分水闸 | C22: 箱涵 | D22: 跌水 | E22: 农桥 | F22: 斗口
A23: 干渠 | B23: 12 | C23: 4 | D23: 22
A24: 1-1支渠 | B24: 15 | C24: 1 | E24: 3
A25: 1-2支渠 | B25: 13 | E25: 2
A26: 1-3支渠 | B26: 15 | E26: 2 | J26: =157+117+716 -> 990
A27: 1-4支渠 | B27: 12 | D27: 1 | E27: 2
A28: 1-5支渠 | B28: 6 | E28: 1
A29: 2-1支渠 | B29: 22 | C29: 1 | E29: 17
A30: 2-2支渠 | B30: 12 | C30: 2 | E30: 3
A31: 2-3支渠 | B31: 11 | C31: 1 | E31: 14
A32: 2-4支渠 | B32: 10 | C32: 1 | E32: 3
A33: 2-5支渠 | B33: 9 | C33: 1 | E33: 10
A34: 2-6支渠 | B34: 8 | C34: 1 | E34: 2
A35: 2-7支渠 | B35: 11 | C35: 1 | E35: 7
A36: 斗渠 | C36: 13 | E36: 51
A37: 合计 | B37: =SUM(B23:B36) -> 156 | C37: =SUM(C23:C36) -> 26 | D37: =SUM(D23:D36) -> 23 | E37: =SUM(E23:E36) -> 117 | F37: 668

Sheet 试算
B1: 灌水率
B2: 0.185
B3: 利用系数
B4: 干渠 | C4: 支渠 | D4: 斗渠 | E4: 农渠 | F4: 渠系 | G4: 田间 | H4: 灌溉
B5: 0.91 | C5: 0.91 | D5: 0.87 | E5: 0.88 | F5: 0.64 | G5: 0.87 | H5: =ROUND(F5*G5,2) -> 0.56
B7: 干渠流量
B8: 3
B12: 现状干渠
B13: 底宽 | C13: 深 | D13: 比降 | L13: =L14+1.16 -> 1.65
B14: 3 | C14: 2 | D14: =0.21/88 -> 0.0023863636 | L14: =L15+0.2 -> 0.49
B15: 干渠 | K15: =1.168+1.168/4+0.2 -> 1.66 | L15: =1.16/4 -> 0.29
B16: b | C16: m | D16: i | E16: n | F16: h | G16: v | H16: q
A17: 加大 | B17: 1.7 | C17: 0 | D17: 0.002 | E17: 0.014 | F17: 1.12 | G17: 1.97 | H17: 3.75 | K17: =1/550 -> 0.0018181818
A18: 设计 | F18: 0.94 | G18: 1.87 | H18: 3
A19: 尺寸 | B19: 1.7*1.6 | C19: =1.12/4+0.2 -> 0.48
C20: =C19+1.12 -> 1.6
A22: 加大 | B22: 1 | C22: 1.5 | D22: 0.001 | E22: 0.014 | F22: 1 | G22: 1.5
A23: 设计 | F23: 0.9 | G23: 1.42
B24: 1*1.5 | I24: 1.5
A25: 加大 | B25: 1 | C25: 1.5 | D25: 0.002 | E25: 0.014 | F25: 0.85 | G25: 1.95 | I25: 1.42
A26: 设计 | F26: 0.77 | G26: 1.85
F27: =0.85+0.85*0.25+0.2 -> 1.2625
B28: 1*1.3
A30: 加大 | B30: 1 | C30: 1.5 | D30: 0.0005 | E30: 0.014 | F30: 1.17 | G30: 1.16
A31: 设计 | F31: 1.06 | G31: 1.1
E34: =13200-9700 -> 3500 | F34: =1665.41-1660.9 -> 4.51
F35: =F34/E34 -> 0.0012885714
A39: 干 | B39: 13.283 | C39: =B39*80 -> 1062.64
A40: 支1 | B40: 24.32 | C40: =B40*25 -> 608
A41: 支2 | B41: 30.1 | C41: =B41*23 -> 692.3 | J41: =0.2*3.2+0.25*1.7 -> 1.065
A42: 斗1 | B42: 44.9 | C42: =B42*22 -> 987.8
A43: 斗2 | B43: 45.5 | C43: =B43*22 -> 1001
C44: =SUM(C39:C43) -> 4351.74
C45: =C44*1.8 -> 7833.132

Sheet 干渠
B1: 备注 | C1: 桩号 | D1: 流量 | F1: 流速 | H1: 水深 | J1: 糙率 | K1: 比降 | M1: 底宽 | N1: 边坡系数 | S1: 超高 | T1: 渠深 | U1: 上口宽度 | V1: 地面高程 | W1: 渠底高程 | X1: 设计水位 | Y1: 备注
D2: Q大 | E2: Q设 | F2: V大 | G2: V设 | H2: H大 | I2: H设 | J2: n | K2: i | M2: b | N2: m | O2: B设 | P2: A设 | Q2: B大 | R2: A大 | S2: Fb | T2: h | U2: B
C3: km+m | D3: m3/s | E3: m3/s | F3: m/s | G3: m/s | H3: m | I3: m | M3: m | S3: m | T3: m | U3: m | V3: m | W3: m | X3: m
A4: 分水闸 | C4: =Sheet1!C2 -> 0 | D4: =E4*1.25 -> 3.75 | E4: 3
A5: 矩形钢筋混凝土渠 | C5: =Sheet1!C6 -> 30 | D5: =E5*1.25 -> 3.75 | E5: 3 | F5: =ROUND(D5/R5,2) -> 1.97 | G5: =ROUND(E5/P5,2) -> 1.88 | H5: 1.12 | I5: 0.87 | J5: 0.014 | K5: =Sheet1!K6 -> 0.002 | L5: ="1/"&ROUND(1/K5,0) -> 1/500 | M5: 1.7 | N5: 0 | O5: =ROUND(M5+2*N5*I5,2) -> 1.7 | P5: 1.6 | Q5: =ROUND(M5+N5*2*H5,2) -> 1.7 | R5: =ROUND((M5+Q5)*H5/2,2) -> 1.9 | S5: =T5-H5 -> 0.48 | T5: 1.6 | U5: =M5+T5*N5 -> 1.7 | V5: =Sheet1!E6 -> 1729.58 | W5: =Sheet1!G6 -> 1728 | X5: =W5+I5 -> 1728.87 | AA5: =X5-W5+G5*G5/2/9.81 -> 1.0501427 | AB5: =X5-W5 -> 0.87
C6: =Sheet1!C8 -> 50 | D6: =E6*1.25 -> 3.75 | E6: 3 | F6: =ROUND(D6/R6,2) -> 1.97 | G6: =ROUND(E6/P6,2) -> 1.88 | H6: 1.12 | I6: 0.87 | J6: 0.014 | K6: =Sheet1!K7 -> 0.002 | L6: ="1/"&ROUND(1/K6,0) -> 1/500 | M6: 1.7 | N6: 0 | O6: =ROUND(M6+2*N6*I6,2) -> 1.7 | P6: 1.6 | Q6: =ROUND(M6+N6*2*H6,2) -> 1.7 | R6: =ROUND((M6+Q6)*H6/2,2) -> 1.9 | S6: =T6-H6 -> 0.48 | T6: 1.6 | U6: =M6+T6*N6 -> 1.7 | V6: =Sheet1!E8 -> 1728.9 | W6: =Sheet1!G8 -> 1727.96 | X6: =W6+I6 -> 1728.83
C7: =Sheet1!C9 -> 100 | D7: =E7*1.25 -> 3.75 | E7: 3 | F7: =ROUND(D7/R7,2) -> 1.97 | G7: =ROUND(E7/P7,2) -> 1.88 | H7: 1.12 | I7: 0.87 | J7: 0.014 | K7: =Sheet1!K8 -> 0.002 | L7: ="1/"&ROUND(1/K7,0) -> 1/500 | M7: 1.7 | N7: 0 | O7: =ROUND(M7+2*N7*I7,2) -> 1.7 | P7: 1.6 | Q7: =ROUND(M7+N7*2*H7,2) -> 1.7 | R7: =ROUND((M7+Q7)*H7/2,2) -> 1.9 | S7: =T7-H7 -> 0.48 | T7: 1.6 | U7: =M7+T7*N7 -> 1.7 | V7: =Sheet1!E9 -> 1729.73 | W7: =Sheet1!G9 -> 1727.86 | X7: =W7+I7 -> 1728.73
C8: =Sheet1!C10 -> 150 | D8: =E8*1.25 -> 3.75 | E8: 3 | F8: =ROUND(D8/R8,2) -> 1.97 | G8: =ROUND(E8/P8,2) -> 1.88 | H8: 1.12 | I8: 0.87 | J8: 0.014 | K8: =Sheet1!K9 -> 0.002 | L8: ="1/"&ROUND(1/K8,0) -> 1/500 | M8: 1.7 | N8: 0 | O8: =ROUND(M8+2*N8*I8,2) -> 1.7 | P8: 1.6 | Q8: =ROUND(M8+N8*2*H8,2) -> 1.7 | R8: =ROUND((M8+Q8)*H8/2,2) -> 1.9 | S8: =T8-H8 -> 0.48 | T8: 1.6 | U8: =M8+T8*N8 -> 1.7 | V8: =Sheet1!E10 -> 1728.71 | W8: =Sheet1!G10 -> 1727.76 | X8: =W8+I8 -> 1728.63
C9: =Sheet1!C11 -> 200 | D9: =E9*1.25 -> 3.75 | E9: 3 | F9: =ROUND(D9/R9,2) -> 1.97 | G9: =ROUND(E9/P9,2) -> 1.88 | H9: 1.12 | I9: 0.87 | J9: 0.014 | K9: =Sheet1!K10 -> 0.002 | L9: ="1/"&ROUND(1/K9,0) -> 1/500 | M9: 1.7 | N9: 0 | O9: =ROUND(M9+2*N9*I9,2) -> 1.7 | P9: 1.6 | Q9: =ROUND(M9+N9*2*H9,2) -> 1.7 | R9: =ROUND((M9+Q9)*H9/2,2) -> 1.9 | S9: =T9-H9 -> 0.48 | T9: 1.6 | U9: =M9+T9*N9 -> 1.7 | V9: =Sheet1!E11 -> 1727.89 | W9: =Sheet1!G11 -> 1727.66 | X9: =W9+I9 -> 1728.53
B10: 1#跌水2.2m | C10: =Sheet1!C12 -> 210 | D10: =E10*1.25 -> 3.75 | E10: 3 | F10: =ROUND(D10/R10,2) -> 1.97 | G10: =ROUND(E10/P10,2) -> 1.88 | H10: 1.12 | I10: 0.87 | J10: 0.014 | K10: =Sheet1!K11 -> 0.002 | L10: ="1/"&ROUND(1/K10,0) -> 1/500 | M10: 1.7 | N10: 0 | O10: =ROUND(M10+2*N10*I10,2) -> 1.7 | P10: 1.6 | Q10: =ROUND(M10+N10*2*H10,2) -> 1.7 | R10: =ROUND((M10+Q10)*H10/2,2) -> 1.9 | S10: =T10-H10 -> 0.48 | T10: 1.6 | U10: =M10+T10*N10 -> 1.7 | V10: =Sheet1!E12 -> 1727.73 | W10: =Sheet1!G12 -> 1727.64 | X10: =W10+I10 -> 1728.51 | Y10: 1#跌水2.2m
C11: =Sheet1!C13 -> 213 | D11: =E11*1.25 -> 3.75 | E11: 3 | F11: =ROUND(D11/R11,2) -> 1.97 | G11: =ROUND(E11/P11,2) -> 1.88 | H11: 1.12 | I11: 0.87 | J11: 0.014 | K11: =Sheet1!K12 -> 0.002 | L11: ="1/"&ROUND(1/K11,0) -> 1/500 | M11: 1.7 | N11: 0 | O11: =ROUND(M11+2*N11*I11,2) -> 1.7 | P11: 1.6 | Q11: =ROUND(M11+N11*2*H11,2) -> 1.7 | R11: =ROUND((M11+Q11)*H11/2,2) -> 1.9 | S11: =T11-H11 -> 0.48 | T11: 1.6 | U11: =M11+T11*N11 -> 1.7 | V11: =Sheet1!E13 -> 1727.73 | W11: =Sheet1!G13 -> 1725.44 | X11: =W11+I11 -> 1726.31
C12: =Sheet1!C14 -> 250 | D12: =E12*1.25 -> 3.75 | E12: 3 | F12: =ROUND(D12/R12,2) -> 1.97 | G12: =ROUND(E12/P12,2) -> 1.88 | H12: 1.12 | I12: 0.87 | J12: 0.014 | K12: =Sheet1!K13 -> 0.002 | L12: ="1/"&ROUND(1/K12,0) -> 1/500 | M12: 1.7 | N12: 0 | O12: =ROUND(M12+2*N12*I12,2) -> 1.7 | P12: 1.6 | Q12: =ROUND(M12+N12*2*H12,2) -> 1.7 | R12: =ROUND((M12+Q12)*H12/2,2) -> 1.9 | S12: =T12-H12 -> 0.48 | T12: 1.6 | U12: =M12+T12*N12 -> 1.7 | V12: =Sheet1!E14 -> 1727.17 | W12: =Sheet1!G14 -> 1725.36 | X12: =W12+I12 -> 1726.23
C13: =Sheet1!C15 -> 300 | D13: =E13*1.25 -> 3.75 | E13: 3 | F13: =ROUND(D13/R13,2) -> 1.97 | G13: =ROUND(E13/P13,2) -> 1.88 | H13: 1.12 | I13: 0.87 | J13: 0.014 | K13: =Sheet1!K14 -> 0.002 | L13: ="1/"&ROUND(1/K13,0) -> 1/500 | M13: 1.7 | N13: 0 | O13: =ROUND(M13+2*N13*I13,2) -> 1.7 | P13: 1.6 | Q13: =ROUND(M13+N13*2*H13,2) -> 1.7 | R13: =ROUND((M13+Q13)*H13/2,2) -> 1.9 | S13: =T13-H13 -> 0.48 | T13: 1.6 | U13: =M13+T13*N13 -> 1.7 | V13: =Sheet1!E15 -> 1726.51 | W13: =Sheet1!G15 -> 1725.26 | X13: =W13+I13 -> 1726.13
C14: =Sheet1!C16 -> 350 | D14: =E14*1.25 -> 3.75 | E14: 3 | F14: =ROUND(D14/R14,2) -> 1.97 | G14: =ROUND(E14/P14,2) -> 1.88 | H14: 1.12 | I14: 0.87 | J14: 0.014 | K14: =Sheet1!K15 -> 0.002 | L14: ="1/"&ROUND(1/K14,0) -> 1/500 | M14: 1.7 | N14: 0 | O14: =ROUND(M14+2*N14*I14,2) -> 1.7 | P14: 1.6 | Q14: =ROUND(M14+N14*2*H14,2) -> 1.7 | R14: =ROUND((M14+Q14)*H14/2,2) -> 1.9 | S14: =T14-H14 -> 0.48 | T14: 1.6 | U14: =M14+T14*N14 -> 1.7 | V14: =Sheet1!E16 -> 1725.77 | W14: =Sheet1!G16 -> 1725.16 | X14: =W14+I14 -> 1726.03
C15: =Sheet1!C17 -> 400 | D15: =E15*1.25 -> 3.75 | E15: 3 | F15: =ROUND(D15/R15,2) -> 1.97 | G15: =ROUND(E15/P15,2) -> 1.88 | H15: 1.12 | I15: 0.87 | J15: 0.014 | K15: =Sheet1!K16 -> 0.002 | L15: ="1/"&ROUND(1/K15,0) -> 1/500 | M15: 1.7 | N15: 0 | O15: =ROUND(M15+2*N15*I15,2) -> 1.7 | P15: 1.6 | Q15: =ROUND(M15+N15*2*H15,2) -> 1.7 | R15: =ROUND((M15+Q15)*H15/2,2) -> 1.9 | S15: =T15-H15 -> 0.48 | T15: 1.6 | U15: =M15+T15*N15 -> 1.7 | V15: =Sheet1!E17 -> 1725.11 | W15: =Sheet1!G17 -> 1725.06 | X15: =W15+I15 -> 1725.93
B16: 2#跌水2.2m | C16: =Sheet1!C18 -> 420 | D16: =E16*1.25 -> 3.75 | E16: 3 | F16: =ROUND(D16/R16,2) -> 1.97 | G16: =ROUND(E16/P16,2) -> 1.88 | H16: 1.12 | I16: 0.87 | J16: 0.014 | K16: =Sheet1!K17 -> 0.002 | L16: ="1/"&ROUND(1/K16,0) -> 1/500 | M16: 1.7 | N16: 0 | O16: =ROUND(M16+2*N16*I16,2) -> 1.7 | P16: 1.6 | Q16: =ROUND(M16+N16*2*H16,2) -> 1.7 | R16: =ROUND((M16+Q16)*H16/2,2) -> 1.9 | S16: =T16-H16 -> 0.48 | T16: 1.6 | U16: =M16+T16*N16 -> 1.7 | V16: =Sheet1!E18 -> 1724.79 | W16: =Sheet1!G18 -> 1725.02 | X16: =W16+I16 -> 1725.89 | Y16: 2#跌水2.2m
C17: =Sheet1!C19 -> 423 | D17: =E17*1.25 -> 3.75 | E17: 3 | F17: =ROUND(D17/R17,2) -> 1.97 | G17: =ROUND(E17/P17,2) -> 1.88 | H17: 1.12 | I17: 0.87 | J17: 0.014 | K17: =Sheet1!K18 -> 0.002 | L17: ="1/"&ROUND(1/K17,0) -> 1/500 | M17: 1.7 | N17: 0 | O17: =ROUND(M17+2*N17*I17,2) -> 1.7 | P17: 1.6 | Q17: =ROUND(M17+N17*2*H17,2) -> 1.7 | R17: =ROUND((M17+Q17)*H17/2,2) -> 1.9 | S17: =T17-H17 -> 0.48 | T17: 1.6 | U17: =M17+T17*N17 -> 1.7 | V17: =Sheet1!E19 -> 1724.79 | W17: =Sheet1!G19 -> 1722.82 | X17: =W17+I17 -> 1723.69
C18: =Sheet1!C20 -> 430 | D18: =E18*1.25 -> 3.75 | E18: 3 | F18: =ROUND(D18/R18,2) -> 1.97 | G18: =ROUND(E18/P18,2) -> 1.88 | H18: 1.12 | I18: 0.87 | J18: 0.014 | K18: =Sheet1!K19 -> 0.002 | L18: ="1/"&ROUND(1/K18,0) -> 1/500 | M18: 1.7 | N18: 0 | O18: =ROUND(M18+2*N18*I18,2) -> 1.7 | P18: 1.6 | Q18: =ROUND(M18+N18*2*H18,2) -> 1.7 | R18: =ROUND((M18+Q18)*H18/2,2) -> 1.9 | S18: =T18-H18 -> 0.48 | T18: 1.6 | U18: =M18+T18*N18 -> 1.7 | V18: =Sheet1!E20 -> 1724.65 | W18: =Sheet1!G20 -> 1722.82 | X18: =W18+I18 -> 1723.69
C19: =Sheet1!C21 -> 460 | D19: =E19*1.25 -> 3.75 | E19: 3 | F19: =ROUND(D19/R19,2) -> 1.97 | G19: =ROUND(E19/P19,2) -> 1.88 | H19: 1.12 | I19: 0.87 | J19: 0.014 | K19: =Sheet1!K20 -> 0.002 | L19: ="1/"&ROUND(1/K19,0) -> 1/500 | M19: 1.7 | N19: 0 | O19: =ROUND(M19+2*N19*I19,2) -> 1.7 | P19: 1.6 | Q19: =ROUND(M19+N19*2*H19,2) -> 1.7 | R19: =ROUND((M19+Q19)*H19/2,2) -> 1.9 | S19: =T19-H19 -> 0.48 | T19: 1.6 | U19: =M19+T19*N19 -> 1.7 | V19: =Sheet1!E21 -> 1724.27 | W19: =Sheet1!G21 -> 1722.76 | X19: =W19+I19 -> 1723.63
C20: =Sheet1!C22 -> 464 | D20: =E20*1.25 -> 3.75 | E20: 3 | F20: =ROUND(D20/R20,2) -> 1.97 | G20: =ROUND(E20/P20,2) -> 1.88 | H20: 1.12 | I20: 0.87 | J20: 0.014 | K20: =Sheet1!K21 -> 0.002 | L20: ="1/"&ROUND(1/K20,0) -> 1/500 | M20: 1.7 | N20: 0 | O20: =ROUND(M20+2*N20*I20,2) -> 1.7 | P20: 1.6 | Q20: =ROUND(M20+N20*2*H20,2) -> 1.7 | R20: =ROUND((M20+Q20)*H20/2,2) -> 1.9 | S20: =T20-H20 -> 0.48 | T20: 1.6 | U20: =M20+T20*N20 -> 1.7 | V20: =Sheet1!E22 -> 1724.03 | W20: =Sheet1!G22 -> 1722.75 | X20: =W20+I20 -> 1723.62
C21: =Sheet1!C23 -> 500 | D21: =E21*1.25 -> 3.75 | E21: 3 | F21: =ROUND(D21/R21,2) -> 1.97 | G21: =ROUND(E21/P21,2) -> 1.88 | H21: 1.12 | I21: 0.87 | J21: 0.014 | K21: =Sheet1!K22 -> 0.002 | L21: ="1/"&ROUND(1/K21,0) -> 1/500 | M21: 1.7 | N21: 0 | O21: =ROUND(M21+2*N21*I21,2) -> 1.7 | P21: 1.6 | Q21: =ROUND(M21+N21*2*H21,2) -> 1.7 | R21: =ROUND((M21+Q21)*H21/2,2) -> 1.9 | S21: =T21-H21 -> 0.48 | T21: 1.6 | U21: =M21+T21*N21 -> 1.7 | V21: =Sheet1!E23 -> 1723.46 | W21: =Sheet1!G23 -> 1722.68 | X21: =W21+I21 -> 1723.55
C22: =Sheet1!C24 -> 550 | D22: =E22*1.25 -> 3.75 | E22: 3 | F22: =ROUND(D22/R22,2) -> 1.97 | G22: =ROUND(E22/P22,2) -> 1.88 | H22: 1.12 | I22: 0.87 | J22: 0.014 | K22: =Sheet1!K23 -> 0.002 | L22: ="1/"&ROUND(1/K22,0) -> 1/500 | M22: 1.7 | N22: 0 | O22: =ROUND(M22+2*N22*I22,2) -> 1.7 | P22: 1.6 | Q22: =ROUND(M22+N22*2*H22,2) -> 1.7 | R22: =ROUND((M22+Q22)*H22/2,2) -> 1.9 | S22: =T22-H22 -> 0.48 | T22: 1.6 | U22: =M22+T22*N22 -> 1.7 | V22: =Sheet1!E24 -> 1722.89 | W22: =Sheet1!G24 -> 1722.58 | X22: =W22+I22 -> 1723.45
C23: =Sheet1!C25 -> 600 | D23: =E23*1.25 -> 3.75 | E23: 3 | F23: =ROUND(D23/R23,2) -> 1.97 | G23: =ROUND(E23/P23,2) -> 1.88 | H23: 1.12 | I23: 0.87 | J23: 0.014 | K23: =Sheet1!K24 -> 0.002 | L23: ="1/"&ROUND(1/K23,0) -> 1/500 | M23: 1.7 | N23: 0 | O23: =ROUND(M23+2*N23*I23,2) -> 1.7 | P23: 1.6 | Q23: =ROUND(M23+N23*2*H23,2) -> 1.7 | R23: =ROUND((M23+Q23)*H23/2,2) -> 1.9 | S23: =T23-H23 -> 0.48 | T23: 1.6 | U23: =M23+T23*N23 -> 1.7 | V23: =Sheet1!E25 -> 1722.38 | W23: =Sheet1!G25 -> 1722.48 | X23: =W23+I23 -> 1723.35
C24: =Sheet1!C26 -> 610 | D24: =E24*1.25 -> 3.75 | E24: 3 | F24: =ROUND(D24/R24,2) -> 1.97 | G24: =ROUND(E24/P24,2) -> 1.88 | H24: 1.12 | I24: 0.87 | J24: 0.014 | K24: =Sheet1!K25 -> 0.002 | L24: ="1/"&ROUND(1/K24,0) -> 1/500 | M24: 1.7 | N24: 0 | O24: =ROUND(M24+2*N24*I24,2) -> 1.7 | P24: 1.6 | Q24: =ROUND(M24+N24*2*H24,2) -> 1.7 | R24: =ROUND((M24+Q24)*H24/2,2) -> 1.9 | S24: =T24-H24 -> 0.48 | T24: 1.6 | U24: =M24+T24*N24 -> 1.7 | V24: =Sheet1!E26 -> 1722.62 | W24: =Sheet1!G26 -> 1722.46 | X24: =W24+I24 -> 1723.33
C25: =Sheet1!C27 -> 650 | D25: =E25*1.25 -> 3.75 | E25: 3 | F25: =ROUND(D25/R25,2) -> 1.97 | G25: =ROUND(E25/P25,2) -> 1.88 | H25: 1.12 | I25: 0.87 | J25: 0.014 | K25: =Sheet1!K26 -> 0.002 | L25: ="1/"&ROUND(1/K25,0) -> 1/500 | M25: 1.7 | N25: 0 | O25: =ROUND(M25+2*N25*I25,2) -> 1.7 | P25: 1.6 | Q25: =ROUND(M25+N25*2*H25,2) -> 1.7 | R25: =ROUND((M25+Q25)*H25/2,2) -> 1.9 | S25: =T25-H25 -> 0.48 | T25: 1.6 | U25: =M25+T25*N25 -> 1.7 | V25: =Sheet1!E27 -> 1722.22 | W25: =Sheet1!G27 -> 1722.38 | X25: =W25+I25 -> 1723.25
B26: 3#跌水2.2m | C26: =Sheet1!C28 -> 660 | D26: =E26*1.25 -> 3.75 | E26: 3 | F26: =ROUND(D26/R26,2) -> 1.97 | G26: =ROUND(E26/P26,2) -> 1.88 | H26: 1.12 | I26: 0.87 | J26: 0.014 | K26: =Sheet1!K27 -> 0.002 | L26: ="1/"&ROUND(1/K26,0) -> 1/500 | M26: 1.7 | N26: 0 | O26: =ROUND(M26+2*N26*I26,2) -> 1.7 | P26: 1.6 | Q26: =ROUND(M26+N26*2*H26,2) -> 1.7 | R26: =ROUND((M26+Q26)*H26/2,2) -> 1.9 | S26: =T26-H26 -> 0.48 | T26: 1.6 | U26: =M26+T26*N26 -> 1.7 | V26: =Sheet1!E28 -> 1722.12 | W26: =Sheet1!G28 -> 1722.36 | X26: =W26+I26 -> 1723.23 | Y26: 3#跌水2.2m
C27: =Sheet1!C29 -> 663 | D27: =E27*1.25 -> 3.75 | E27: 3 | F27: =ROUND(D27/R27,2) -> 1.97 | G27: =ROUND(E27/P27,2) -> 1.88 | H27: 1.12 | I27: 0.87 | J27: 0.014 | K27: =Sheet1!K28 -> 0.002 | L27: ="1/"&ROUND(1/K27,0) -> 1/500 | M27: 1.7 | N27: 0 | O27: =ROUND(M27+2*N27*I27,2) -> 1.7 | P27: 1.6 | Q27: =ROUND(M27+N27*2*H27,2) -> 1.7 | R27: =ROUND((M27+Q27)*H27/2,2) -> 1.9 | S27: =T27-H27 -> 0.48 | T27: 1.6 | U27: =M27+T27*N27 -> 1.7 | V27: =Sheet1!E29 -> 1722.09 | W27: =Sheet1!G29 -> 1720.16 | X27: =W27+I27 -> 1721.03
C28: =Sheet1!C30 -> 700 | D28: =E28*1.25 -> 3.75 | E28: 3 | F28: =ROUND(D28/R28,2) -> 1.97 | G28: =ROUND(E28/P28,2) -> 1.88 | H28: 1.12 | I28: 0.87 | J28: 0.014 | K28: =Sheet1!K29 -> 0.002 | L28: ="1/"&ROUND(1/K28,0) -> 1/500 | M28: 1.7 | N28: 0 | O28: =ROUND(M28+2*N28*I28,2) -> 1.7 | P28: 1.6 | Q28: =ROUND(M28+N28*2*H28,2) -> 1.7 | R28: =ROUND((M28+Q28)*H28/2,2) -> 1.9 | S28: =T28-H28 -> 0.48 | T28: 1.6 | U28: =M28+T28*N28 -> 1.7 | V28: =Sheet1!E30 -> 1721.72 | W28: =Sheet1!G30 -> 1720.08 | X28: =W28+I28 -> 1720.95
C29: =Sheet1!C31 -> 710 | D29: =E29*1.25 -> 3.75 | E29: 3 | F29: =ROUND(D29/R29,2) -> 1.97 | G29: =ROUND(E29/P29,2) -> 1.88 | H29: 1.12 | I29: 0.87 | J29: 0.014 | K29: =Sheet1!K30 -> 0.002 | L29: ="1/"&ROUND(1/K29,0) -> 1/500 | M29: 1.7 | N29: 0 | O29: =ROUND(M29+2*N29*I29,2) -> 1.7 | P29: 1.6 | Q29: =ROUND(M29+N29*2*H29,2) -> 1.7 | R29: =ROUND((M29+Q29)*H29/2,2) -> 1.9 | S29: =T29-H29 -> 0.48 | T29: 1.6 | U29: =M29+T29*N29 -> 1.7 | V29: =Sheet1!E31 -> 1721.61 | W29: =Sheet1!G31 -> 1720.06 | X29: =W29+I29 -> 1720.93
C30: =Sheet1!C32 -> 750 | D30: =E30*1.25 -> 3.75 | E30: 3 | F30: =ROUND(D30/R30,2) -> 1.97 | G30: =ROUND(E30/P30,2) -> 1.88 | H30: 1.12 | I30: 0.87 | J30: 0.014 | K30: =Sheet1!K31 -> 0.002 | L30: ="1/"&ROUND(1/K30,0) -> 1/500 | M30: 1.7 | N30: 0 | O30: =ROUND(M30+2*N30*I30,2) -> 1.7 | P30: 1.6 | Q30: =ROUND(M30+N30*2*H30,2) -> 1.7 | R30: =ROUND((M30+Q30)*H30/2,2) -> 1.9 | S30: =T30-H30 -> 0.48 | T30: 1.6 | U30: =M30+T30*N30 -> 1.7 | V30: =Sheet1!E32 -> 1721.2 | W30: =Sheet1!G32 -> 1719.98 | X30: =W30+I30 -> 1720.85
C31: =Sheet1!C33 -> 800 | D31: =E31*1.25 -> 3.75 | E31: 3 | F31: =ROUND(D31/R31,2) -> 1.97 | G31: =ROUND(E31/P31,2) -> 1.88 | H31: 1.12 | I31: 0.87 | J31: 0.014 | K31: =Sheet1!K32 -> 0.002 | L31: ="1/"&ROUND(1/K31,0) -> 1/500 | M31: 1.7 | N31: 0 | O31: =ROUND(M31+2*N31*I31,2) -> 1.7 | P31: 1.6 | Q31: =ROUND(M31+N31*2*H31,2) -> 1.7 | R31: =ROUND((M31+Q31)*H31/2,2) -> 1.9 | S31: =T31-H31 -> 0.48 | T31: 1.6 | U31: =M31+T31*N31 -> 1.7 | V31: =Sheet1!E33 -> 1720.6 | W31: =Sheet1!G33 -> 1719.88 | X31: =W31+I31 -> 1720.75
C32: =Sheet1!C34 -> 850 | D32: =E32*1.25 -> 3.75 | E32: 3 | F32: =ROUND(D32/R32,2) -> 1.97 | G32: =ROUND(E32/P32,2) -> 1.88 | H32: 1.12 | I32: 0.87 | J32: 0.014 | K32: =Sheet1!K33 -> 0.002 | L32: ="1/"&ROUND(1/K32,0) -> 1/500 | M32: 1.7 | N32: 0 | O32: =ROUND(M32+2*N32*I32,2) -> 1.7 | P32: 1.6 | Q32: =ROUND(M32+N32*2*H32,2) -> 1.7 | R32: =ROUND((M32+Q32)*H32/2,2) -> 1.9 | S32: =T32-H32 -> 0.48 | T32: 1.6 | U32: =M32+T32*N32 -> 1.7 | V32: =Sheet1!E34 -> 1720 | W32: =Sheet1!G34 -> 1719.78 | X32: =W32+I32 -> 1720.65
B33: 4#跌水2.2m | C33: =Sheet1!C35 -> 880 | D33: =E33*1.25 -> 3.75 | E33: 3 | F33: =ROUND(D33/R33,2) -> 1.97 | G33: =ROUND(E33/P33,2) -> 1.88 | H33: 1.12 | I33: 0.87 | J33: 0.014 | K33: =Sheet1!K34 -> 0.002 | L33: ="1/"&ROUND(1/K33,0) -> 1/500 | M33: 1.7 | N33: 0 | O33: =ROUND(M33+2*N33*I33,2) -> 1.7 | P33: 1.6 | Q33: =ROUND(M33+N33*2*H33,2) -> 1.7 | R33: =ROUND((M33+Q33)*H33/2,2) -> 1.9 | S33: =T33-H33 -> 0.48 | T33: 1.6 | U33: =M33+T33*N33 -> 1.7 | V33: =Sheet1!E35 -> 1719.5 | W33: =Sheet1!G35 -> 1719.72 | X33: =W33+I33 -> 1720.59 | Y33: 4#跌水2.2m
C34: =Sheet1!C36 -> 882 | D34: =E34*1.25 -> 3.75 | E34: 3 | F34: =ROUND(D34/R34,2) -> 1.97 | G34: =ROUND(E34/P34,2) -> 1.88 | H34: 1.12 | I34: 0.87 | J34: 0.014 | K34: =Sheet1!K35 -> 0.002 | L34: ="1/"&ROUND(1/K34,0) -> 1/500 | M34: 1.7 | N34: 0 | O34: =ROUND(M34+2*N34*I34,2) -> 1.7 | P34: 1.6 | Q34: =ROUND(M34+N34*2*H34,2) -> 1.7 | R34: =ROUND((M34+Q34)*H34/2,2) -> 1.9 | S34: =T34-H34 -> 0.48 | T34: 1.6 | U34: =M34+T34*N34 -> 1.7 | V34: =Sheet1!E36 -> 1719.49 | W34: =Sheet1!G36 -> 1717.52 | X34: =W34+I34 -> 1718.39
C35: =Sheet1!C37 -> 900 | D35: =E35*1.25 -> 3.75 | E35: 3 | F35: =ROUND(D35/R35,2) -> 1.97 | G35: =ROUND(E35/P35,2) -> 1.88 | H35: 1.12 | I35: 0.87 | J35: 0.014 | K35: =Sheet1!K36 -> 0.002 | L35: ="1/"&ROUND(1/K35,0) -> 1/500 | M35: 1.7 | N35: 0 | O35: =ROUND(M35+2*N35*I35,2) -> 1.7 | P35: 1.6 | Q35: =ROUND(M35+N35*2*H35,2) -> 1.7 | R35: =ROUND((M35+Q35)*H35/2,2) -> 1.9 | S35: =T35-H35 -> 0.48 | T35: 1.6 | U35: =M35+T35*N35 -> 1.7 | V35: =Sheet1!E37 -> 1719.274 | W35: =Sheet1!G37 -> 1717.48 | X35: =W35+I35 -> 1718.35
C36: =Sheet1!C38 -> 940 | D36: =E36*1.25 -> 3.75 | E36: 3 | F36: =ROUND(D36/R36,2) -> 1.97 | G36: =ROUND(E36/P36,2) -> 1.88 | H36: 1.12 | I36: 0.87 | J36: 0.014 | K36: =Sheet1!K37 -> 0.002 | L36: ="1/"&ROUND(1/K36,0) -> 1/500 | M36: 1.7 | N36: 0 | O36: =ROUND(M36+2*N36*I36,2) -> 1.7 | P36: 1.6 | Q36: =ROUND(M36+N36*2*H36,2) -> 1.7 | R36: =ROUND((M36+Q36)*H36/2,2) -> 1.9 | S36: =T36-H36 -> 0.48 | T36: 1.6 | U36: =M36+T36*N36 -> 1.7 | V36: =Sheet1!E38 -> 1718.79 | W36: =Sheet1!G38 -> 1717.4 | X36: =W36+I36 -> 1718.27
C37: =Sheet1!C39 -> 950 | D37: =E37*1.25 -> 3.75 | E37: 3 | F37: =ROUND(D37/R37,2) -> 1.97 | G37: =ROUND(E37/P37,2) -> 1.88 | H37: 1.12 | I37: 0.87 | J37: 0.014 | K37: =Sheet1!K38 -> 0.002 | L37: ="1/"&ROUND(1/K37,0) -> 1/500 | M37: 1.7 | N37: 0 | O37: =ROUND(M37+2*N37*I37,2) -> 1.7 | P37: 1.6 | Q37: =ROUND(M37+N37*2*H37,2) -> 1.7 | R37: =ROUND((M37+Q37)*H37/2,2) -> 1.9 | S37: =T37-H37 -> 0.48 | T37: 1.6 | U37: =M37+T37*N37 -> 1.7 | V37: =Sheet1!E39 -> 1718.6 | W37: =Sheet1!G39 -> 1717.38 | X37: =W37+I37 -> 1718.25
C38: =Sheet1!C40 -> 1000 | D38: =E38*1.25 -> 3.75 | E38: 3 | F38: =ROUND(D38/R38,2) -> 1.97 | G38: =ROUND(E38/P38,2) -> 1.88 | H38: 1.12 | I38: 0.87 | J38: 0.014 | K38: =Sheet1!K39 -> 0.002 | L38: ="1/"&ROUND(1/K38,0) -> 1/500 | M38: 1.7 | N38: 0 | O38: =ROUND(M38+2*N38*I38,2) -> 1.7 | P38: 1.6 | Q38: =ROUND(M38+N38*2*H38,2) -> 1.7 | R38: =ROUND((M38+Q38)*H38/2,2) -> 1.9 | S38: =T38-H38 -> 0.48 | T38: 1.6 | U38: =M38+T38*N38 -> 1.7 | V38: =Sheet1!E40 -> 1717.9 | W38: =Sheet1!G40 -> 1717.28 | X38: =W38+I38 -> 1718.15
C39: =Sheet1!C41 -> 1050 | D39: =E39*1.25 -> 3.75 | E39: 3 | F39: =ROUND(D39/R39,2) -> 1.97 | G39: =ROUND(E39/P39,2) -> 1.88 | H39: 1.12 | I39: 0.87 | J39: 0.014 | K39: =Sheet1!K40 -> 0.002 | L39: ="1/"&ROUND(1/K39,0) -> 1/500 | M39: 1.7 | N39: 0 | O39: =ROUND(M39+2*N39*I39,2) -> 1.7 | P39: 1.6 | Q39: =ROUND(M39+N39*2*H39,2) -> 1.7 | R39: =ROUND((M39+Q39)*H39/2,2) -> 1.9 | S39: =T39-H39 -> 0.48 | T39: 1.6 | U39: =M39+T39*N39 -> 1.7 | V39: =Sheet1!E41 -> 1717.67 | W39: =Sheet1!G41 -> 1717.18 | X39: =W39+I39 -> 1718.05
C40: =Sheet1!C42 -> 1100 | D40: =E40*1.25 -> 3.75 | E40: 3 | F40: =ROUND(D40/R40,2) -> 1.97 | G40: =ROUND(E40/P40,2) -> 1.88 | H40: 1.12 | I40: 0.87 | J40: 0.014 | K40: =Sheet1!K41 -> 0.002 | L40: ="1/"&ROUND(1/K40,0) -> 1/500 | M40: 1.7 | N40: 0 | O40: =ROUND(M40+2*N40*I40,2) -> 1.7 | P40: 1.6 | Q40: =ROUND(M40+N40*2*H40,2) -> 1.7 | R40: =ROUND((M40+Q40)*H40/2,2) -> 1.9 | S40: =T40-H40 -> 0.48 | T40: 1.6 | U40: =M40+T40*N40 -> 1.7 | V40: =Sheet1!E42 -> 1717.63 | W40: =Sheet1!G42 -> 1717.08 | X40: =W40+I40 -> 1717.95
...

Sheet 支渠
G1: 灌水率 | H1: 利用系数 | M1: 流量
H2: 田间 | I2: 农渠 | J2: 斗渠 | K2: 支渠
A3: 1-1支渠 | B3: 5871 | C3: 6803 | D3: =C3-B3 -> 932 | E3: 13100 | F3: 13103 | G3: 0.217 | H3: 0.87 | I3: 0.88 | J3: 0.87 | K3: 0.91 | L3: =ROUND(H3*I3*J3*K3,2) -> 0.61 | M3: =ROUND(E3*G3/L3/10000,2) -> 0.47 | N3: =ROUND(M3*1.3,2) -> 0.61 | O3: - | P3: U80 | S3: =0.217*6/0.56 -> 2.325
A4: 1-2支渠 | B4: 6197 | C4: 7224 | D4: =C4-B4 -> 1027 | E4: 19420 | F4: 19415 | G4: =G3 -> 0.217 | L4: =L3 -> 0.61 | M4: =ROUND(E4*G4/L4/10000,2) -> 0.69 | N4: =ROUND(M4*1.3,2) -> 0.9 | O4: 0-3700 | P4: U100 | Q4: 3700- | R4: U80
A5: 1-3支渠 | B5: 4400 | C5: 4900 | D5: =C5-B5 -> 500 | E5: 10930 | F5: 10932 | G5: =G4 -> 0.217 | L5: =L4 -> 0.61 | M5: =ROUND(E5*G5/L5/10000,2) -> 0.39 | N5: =ROUND(M5*1.3,2) -> 0.51 | O5: 0-3300 | P5: U80 | Q5: 3300- | R5: U60
A6: 1-4支渠 | B6: 5310 | E6: 9210 | F6: 9208 | G6: =G5 -> 0.217 | L6: =L5 -> 0.61 | M6: =ROUND(E6*G6/L6/10000,2) -> 0.33 | N6: =ROUND(M6*1.3,2) -> 0.43 | O6: 0-3200 | P6: U60 | Q6: 3200- | R6: U60
A7: 1-5支渠 | B7: 2545 | E7: 3850 | F7: 1219 | G7: =G6 -> 0.217 | L7: =L6 -> 0.61 | M7: =ROUND(E7*G7/L7/10000,2) -> 0.14 | N7: =ROUND(M7*1.3,2) -> 0.18 | O7: 0- | P7: U60
A8: 2-1支渠 | E8: 13090 | F8: 13089 | G8: =G7 -> 0.217 | L8: =L7 -> 0.61 | M8: =ROUND(E8*G8/L8/10000,2) -> 0.47 | N8: =ROUND(M8*1.3,2) -> 0.61 | O8: 0-2610 | P8: U80 | Q8: 2610- | R8: U60
A9: 2-2支渠 | E9: 5940 | F9: 5939 | G9: =G8 -> 0.217 | L9: =L8 -> 0.61 | M9: =ROUND(E9*G9/L9/10000,2) -> 0.21 | N9: =ROUND(M9*1.3,2) -> 0.27 | P9: U60
A10: 2-3支渠 | E10: 4860 | F10: 4853 | G10: =G9 -> 0.217 | L10: =L9 -> 0.61 | M10: =ROUND(E10*G10/L10/10000,2) -> 0.17 | N10: =ROUND(M10*1.3,2) -> 0.22 | P10: U60
A11: 2-4支渠 | E11: 4760 | F11: 4759 | G11: =G10 -> 0.217 | L11: =L10 -> 0.61 | M11: =ROUND(E11*G11/L11/10000,2) -> 0.17 | N11: =ROUND(M11*1.3,2) -> 0.22 | P11: U60
A12: 2-5支渠 | E12: 4330 | F12: 4322 | G12: =G11 -> 0.217 | L12: =L11 -> 0.61 | M12: =ROUND(E12*G12/L12/10000,2) -> 0.15 | N12: =ROUND(M12*1.3,2) -> 0.2 | P12: U60
A13: 2-6支渠 | E13: 4340 | F13: 4336 | G13: =G12 -> 0.217 | L13: =L12 -> 0.61 | M13: =ROUND(E13*G13/L13/10000,2) -> 0.15 | N13: =ROUND(M13*1.3,2) -> 0.2 | P13: U60
A14: 2-7支渠 | E14: 7000 | F14: 6993 | G14: =G13 -> 0.217 | L14: =L13 -> 0.61 | M14: =ROUND(E14*G14/L14/10000,2) -> 0.25 | N14: =ROUND(M14*1.3,2) -> 0.33 | P14: U60
N21: =0.2/1.25 -> 0.16
N24: U100
N25: A1
N26: =3.14*I29^2*(152/360) -> 0.33144444
A28: Q | E28: n | G28: i | H28: 左边 | I28: b | J28: m | L28: h | M28: 右边 | N28: A | O28: X
A29: 0.36 | E29: 0.014 | G29: 0.001 | H29: =ROUND(A29*E29/G29^0.5,3) -> 0.159 | I29: 0.5 | L29: 0.6 | M29: =N31/O31 -> #DIV/0! | N29: =0.5*3.14*I29*I29+2*I29*(L29-I29) -> 0.4925
N30: A5/3 | O30: X2/3
N31: =N29^(5/3) -> 0.30714519 | O31: =O29^(2/3) -> 0
A34: 序号 | B34: 名称 | C34: 位置 | E34: 长度（m） | F34: 设计流量（m3/s）
A35: 1 | B35: 1-1支渠 | C35: 干渠 | D35: =干渠!C191 -> 6600 | E35: ='1-1支渠'!K76 -> 6803 | F35: =M3 -> 0.47
A36: 2 | B36: 1-2支渠 | D36: =干渠!C228 -> 8300 | E36: ='1-2支渠'!K77 -> 7224 | F36: =M4 -> 0.69
A37: 3 | B37: 1-3支渠 | D37: =干渠!C277 -> 10750 | E37: ='1-3支渠'!K54 -> 4900 | F37: =M5 -> 0.39
A38: 4 | B38: 1-4支渠 | D38: =干渠!C299 -> 11850 | E38: ='1-4支渠'!K60 -> 5310 | F38: =M6 -> 0.33
A39: 5 | B39: 1-5支渠 | D39: =干渠!C328 -> 13283 | E39: ='1-5支渠'!K31 -> 2545 | F39: =M7 -> 0.14
A40: 6 | B40: 2-1支渠 | C40: 达乎甫干渠 | E40: ='2-支渠'!B55 -> 4150 | F40: =M8 -> 0.47
A41: 7 | B41: 2-2支渠 | E41: ='2-支渠'!B115 -> 4800 | F41: =M9 -> 0.21
A42: 8 | B42: 2-3支渠 | E42: ='2-支渠'!B174 -> 4400 | F42: =M10 -> 0.17
A43: 9 | B43: 2-4支渠 | E43: ='2-支渠'!B230 -> 4000 | F43: =M11 -> 0.17
A44: 10 | B44: 2-5支渠 | E44: ='2-支渠'!B282 -> 3550 | F44: =M12 -> 0.15
A45: 11 | B45: 2-6支渠 | E45: ='2-支渠'!B330 -> 3400 | F45: =M13 -> 0.15
A46: 12 | B46: 2-7支渠 | E46: ='2-支渠'!B386 -> 5020 | F46: =M14 -> 0.25
A47: 合计 | E47: =SUM(E35:E46) -> 56102

Sheet 1-1支渠
J1: 备注 | K1: 桩号 | L1: 流量 | N1: 流速 | P1: 水深 | R1: 糙率 | S1: 比降 | U1: 规格 | X1: 超高 | Y1: 渠深 | Z1: 地面高程 | AA1: 渠底高程 | AB1: 设计水位 | AC1: 备注
L2: Q大 | M2: Q设 | N2: V大 | O2: V设 | P2: H大 | Q2: H设 | R2: n | S2: i | U2: b | V2: A设 | W2: A大 | X2: Fb | Y2: h
B3: 桩号m | D3: 地面线 | F3: 渠底 | K3: km+m | L3: m3/s | M3: m3/s | N3: m/s | O3: m/s | P3: m | Q3: m | U3: m | X3: m | Y3: m | Z3: m | AA3: m | AB3: m
B4: K0+000 | C4: 0 | D4: 1669.81 | E4: =ROUND(D4,2) -> 1669.81 | F4: 1669.61 | K4: =C4 -> 0 | L4: =ROUND(M4*1.3,2) -> 0.61 | M4: =支渠!M3 -> 0.47
C5: 10 | D5: 1669.76 | E5: =ROUND(D5,2) -> 1669.76 | F5: =E5-1 -> 1668.76 | G5: =E5-F5 -> 1 | H5: 0.004 | K5: =C5 -> 10 | L5: =ROUND(M5*1.3,2) -> 0.61 | M5: =M4 -> 0.47 | N5: =ROUND(L5/W5,2) -> 1.65 | O5: =ROUND(M5/V5,2) -> 1.57 | P5: 0.54 | Q5: 0.46 | R5: 0.015 | S5: =H5 -> 0.004 | T5: ="1/"&ROUND(1/S5,0) -> 1/250 | U5: U80 | V5: 0.3 | W5: 0.37 | X5: =Y5-P5 -> 0.26 | Y5: 0.8 | Z5: =E5 -> 1669.76 | AA5: =F5 -> 1668.76 | AB5: =AA5+Q5 -> 1669.22 | AD5: =Z5-AA5 -> 1 | AE5: =P5*0.25+0.2 -> 0.335 | AF5: =0.54*0.25+0.2 -> 0.335
B6: K0+100 | C6: 100 | D6: 1669.203 | E6: =ROUND(D6,2) -> 1669.2 | F6: =ROUND(F5-(C6-C5)*H5,2) -> 1668.4 | G6: =E6-F6 -> 0.8 | H6: 0.004 | J6: 1-1-1斗渠 | K6: =C6 -> 100 | L6: =ROUND(M6*1.3,2) -> 0.61 | M6: =M5 -> 0.47 | N6: =ROUND(L6/W6,2) -> 1.65 | O6: =ROUND(M6/V6,2) -> 1.57 | P6: =P5 -> 0.54 | Q6: =Q5 -> 0.46 | R6: 0.015 | S6: =H6 -> 0.004 | T6: ="1/"&ROUND(1/S6,0) -> 1/250 | U6: =U5 -> U80 | V6: =V5 -> 0.3 | W6: =W5 -> 0.37 | X6: =Y6-P6 -> 0.26 | Y6: =Y5 -> 0.8 | Z6: =E6 -> 1669.2 | AA6: =F6 -> 1668.4 | AB6: =AA6+Q6 -> 1668.86 | AD6: =Z6-AA6 -> 0.8
B7: K0+200 | C7: 200 | D7: 1668.311 | E7: =ROUND(D7,2) -> 1668.31 | F7: =ROUND(F6-(C7-C6)*H6,2) -> 1668 | G7: =E7-F7 -> 0.31 | H7: 0.004 | K7: =C7 -> 200 | L7: =ROUND(M7*1.3,2) -> 0.61 | M7: =M6 -> 0.47 | N7: =ROUND(L7/W7,2) -> 1.65 | O7: =ROUND(M7/V7,2) -> 1.57 | P7: =P6 -> 0.54 | Q7: =Q6 -> 0.46 | R7: 0.015 | S7: =H7 -> 0.004 | T7: ="1/"&ROUND(1/S7,0) -> 1/250 | U7: =U6 -> U80 | V7: =V6 -> 0.3 | W7: =W6 -> 0.37 | X7: =Y7-P7 -> 0.26 | Y7: =Y6 -> 0.8 | Z7: =E7 -> 1668.31 | AA7: =F7 -> 1668 | AB7: =AA7+Q7 -> 1668.46 | AD7: =Z7-AA7 -> 0.31
B8: K0+300 | C8: 300 | D8: 1667.83 | E8: =ROUND(D8,2) -> 1667.83 | F8: =ROUND(F7-(C8-C7)*H7,2) -> 1667.6 | G8: =E8-F8 -> 0.23 | H8: 0.004 | K8: =C8 -> 300 | L8: =ROUND(M8*1.3,2) -> 0.61 | M8: =M7 -> 0.47 | N8: =ROUND(L8/W8,2) -> 1.65 | O8: =ROUND(M8/V8,2) -> 1.57 | P8: =P7 -> 0.54 | Q8: =Q7 -> 0.46 | R8: 0.015 | S8: =H8 -> 0.004 | T8: ="1/"&ROUND(1/S8,0) -> 1/250 | U8: =U7 -> U80 | V8: =V7 -> 0.3 | W8: =W7 -> 0.37 | X8: =Y8-P8 -> 0.26 | Y8: =Y7 -> 0.8 | Z8: =E8 -> 1667.83 | AA8: =F8 -> 1667.6 | AB8: =AA8+Q8 -> 1668.06 | AD8: =Z8-AA8 -> 0.23
B9: K0+400 | C9: 400 | D9: 1667.487 | E9: =ROUND(D9,2) -> 1667.49 | F9: =ROUND(F8-(C9-C8)*H8,2) -> 1667.2 | G9: =E9-F9 -> 0.29 | H9: 0.004 | K9: =C9 -> 400 | L9: =ROUND(M9*1.3,2) -> 0.61 | M9: =M8 -> 0.47 | N9: =ROUND(L9/W9,2) -> 1.65 | O9: =ROUND(M9/V9,2) -> 1.57 | P9: =P8 -> 0.54 | Q9: =Q8 -> 0.46 | R9: 0.015 | S9: =H9 -> 0.004 | T9: ="1/"&ROUND(1/S9,0) -> 1/250 | U9: =U8 -> U80 | V9: =V8 -> 0.3 | W9: =W8 -> 0.37 | X9: =Y9-P9 -> 0.26 | Y9: =Y8 -> 0.8 | Z9: =E9 -> 1667.49 | AA9: =F9 -> 1667.2 | AB9: =AA9+Q9 -> 1667.66 | AD9: =Z9-AA9 -> 0.29
B10: K0+500 | C10: 500 | D10: 1667.021 | E10: =ROUND(D10,2) -> 1667.02 | F10: =ROUND(F9-(C10-C9)*H9,2) -> 1666.8 | G10: =E10-F10 -> 0.22 | H10: 0.004 | K10: =C10 -> 500 | L10: =ROUND(M10*1.3,2) -> 0.61 | M10: =M9 -> 0.47 | N10: =ROUND(L10/W10,2) -> 1.65 | O10: =ROUND(M10/V10,2) -> 1.57 | P10: =P9 -> 0.54 | Q10: =Q9 -> 0.46 | R10: 0.015 | S10: =H10 -> 0.004 | T10: ="1/"&ROUND(1/S10,0) -> 1/250 | U10: =U9 -> U80 | V10: =V9 -> 0.3 | W10: =W9 -> 0.37 | X10: =Y10-P10 -> 0.26 | Y10: =Y9 -> 0.8 | Z10: =E10 -> 1667.02 | AA10: =F10 -> 1666.8 | AB10: =AA10+Q10 -> 1667.26 | AD10: =Z10-AA10 -> 0.22
B11: K0+600 | C11: 600 | D11: 1666.76 | E11: =ROUND(D11,2) -> 1666.76 | F11: =ROUND(F10-(C11-C10)*H10,2) -> 1666.4 | G11: =E11-F11 -> 0.36 | H11: 0.004 | K11: =C11 -> 600 | L11: =ROUND(M11*1.3,2) -> 0.61 | M11: =M10 -> 0.47 | N11: =ROUND(L11/W11,2) -> 1.65 | O11: =ROUND(M11/V11,2) -> 1.57 | P11: =P10 -> 0.54 | Q11: =Q10 -> 0.46 | R11: 0.015 | S11: =H11 -> 0.004 | T11: ="1/"&ROUND(1/S11,0) -> 1/250 | U11: =U10 -> U80 | V11: =V10 -> 0.3 | W11: =W10 -> 0.37 | X11: =Y11-P11 -> 0.26 | Y11: =Y10 -> 0.8 | Z11: =E11 -> 1666.76 | AA11: =F11 -> 1666.4 | AB11: =AA11+Q11 -> 1666.86 | AD11: =Z11-AA11 -> 0.36
B12: K0+700 | C12: 700 | D12: 1666.211 | E12: =ROUND(D12,2) -> 1666.21 | F12: =ROUND(F11-(C12-C11)*H11,2) -> 1666 | G12: =E12-F12 -> 0.21 | H12: 0.004 | K12: =C12 -> 700 | L12: =ROUND(M12*1.3,2) -> 0.61 | M12: =M11 -> 0.47 | N12: =ROUND(L12/W12,2) -> 1.65 | O12: =ROUND(M12/V12,2) -> 1.57 | P12: =P11 -> 0.54 | Q12: =Q11 -> 0.46 | R12: 0.015 | S12: =H12 -> 0.004 | T12: ="1/"&ROUND(1/S12,0) -> 1/250 | U12: =U11 -> U80 | V12: =V11 -> 0.3 | W12: =W11 -> 0.37 | X12: =Y12-P12 -> 0.26 | Y12: =Y11 -> 0.8 | Z12: =E12 -> 1666.21 | AA12: =F12 -> 1666 | AB12: =AA12+Q12 -> 1666.46 | AD12: =Z12-AA12 -> 0.21
B13: K0+800 | C13: 800 | D13: 1665.776 | E13: =ROUND(D13,2) -> 1665.78 | F13: =ROUND(F12-(C13-C12)*H12,2) -> 1665.6 | G13: =E13-F13 -> 0.18 | H13: 0.004 | K13: =C13 -> 800 | L13: =ROUND(M13*1.3,2) -> 0.61 | M13: =M12 -> 0.47 | N13: =ROUND(L13/W13,2) -> 1.65 | O13: =ROUND(M13/V13,2) -> 1.57 | P13: =P12 -> 0.54 | Q13: =Q12 -> 0.46 | R13: 0.015 | S13: =H13 -> 0.004 | T13: ="1/"&ROUND(1/S13,0) -> 1/250 | U13: =U12 -> U80 | V13: =V12 -> 0.3 | W13: =W12 -> 0.37 | X13: =Y13-P13 -> 0.26 | Y13: =Y12 -> 0.8 | Z13: =E13 -> 1665.78 | AA13: =F13 -> 1665.6 | AB13: =AA13+Q13 -> 1666.06 | AD13: =Z13-AA13 -> 0.18
B14: K0+900 | C14: 900 | D14: 1665.5 | E14: =ROUND(D14,2) -> 1665.5 | F14: =ROUND(F13-(C14-C13)*H13,2) -> 1665.2 | G14: =E14-F14 -> 0.3 | H14: 0.004 | K14: =C14 -> 900 | L14: =ROUND(M14*1.3,2) -> 0.61 | M14: =M13 -> 0.47 | N14: =ROUND(L14/W14,2) -> 1.65 | O14: =ROUND(M14/V14,2) -> 1.57 | P14: =P13 -> 0.54 | Q14: =Q13 -> 0.46 | R14: 0.015 | S14: =H14 -> 0.004 | T14: ="1/"&ROUND(1/S14,0) -> 1/250 | U14: =U13 -> U80 | V14: =V13 -> 0.3 | W14: =W13 -> 0.37 | X14: =Y14-P14 -> 0.26 | Y14: =Y13 -> 0.8 | Z14: =E14 -> 1665.5 | AA14: =F14 -> 1665.2 | AB14: =AA14+Q14 -> 1665.66 | AD14: =Z14-AA14 -> 0.3
B15: K1+000 | C15: 1000 | D15: 1665.064 | E15: =ROUND(D15,2) -> 1665.06 | F15: =ROUND(F14-(C15-C14)*H14,2) -> 1664.8 | G15: =E15-F15 -> 0.26 | H15: 0.004 | K15: =C15 -> 1000 | L15: =ROUND(M15*1.3,2) -> 0.61 | M15: =M14 -> 0.47 | N15: =ROUND(L15/W15,2) -> 1.65 | O15: =ROUND(M15/V15,2) -> 1.57 | P15: =P14 -> 0.54 | Q15: =Q14 -> 0.46 | R15: 0.015 | S15: =H15 -> 0.004 | T15: ="1/"&ROUND(1/S15,0) -> 1/250 | U15: =U14 -> U80 | V15: =V14 -> 0.3 | W15: =W14 -> 0.37 | X15: =Y15-P15 -> 0.26 | Y15: =Y14 -> 0.8 | Z15: =E15 -> 1665.06 | AA15: =F15 -> 1664.8 | AB15: =AA15+Q15 -> 1665.26 | AD15: =Z15-AA15 -> 0.26
B16: K1+100 | C16: 1100 | D16: 1664.563 | E16: =ROUND(D16,2) -> 1664.56 | F16: =ROUND(F15-(C16-C15)*H15,2) -> 1664.4 | G16: =E16-F16 -> 0.16 | H16: 0.004 | K16: =C16 -> 1100 | L16: =ROUND(M16*1.3,2) -> 0.61 | M16: =M15 -> 0.47 | N16: =ROUND(L16/W16,2) -> 1.65 | O16: =ROUND(M16/V16,2) -> 1.57 | P16: =P15 -> 0.54 | Q16: =Q15 -> 0.46 | R16: 0.015 | S16: =H16 -> 0.004 | T16: ="1/"&ROUND(1/S16,0) -> 1/250 | U16: =U15 -> U80 | V16: =V15 -> 0.3 | W16: =W15 -> 0.37 | X16: =Y16-P16 -> 0.26 | Y16: =Y15 -> 0.8 | Z16: =E16 -> 1664.56 | AA16: =F16 -> 1664.4 | AB16: =AA16+Q16 -> 1664.86 | AD16: =Z16-AA16 -> 0.16
C17: 1152 | E17: 1665.5 | F17: =ROUND(F16-(C17-C16)*H16,2) -> 1664.19 | G17: =E17-F17 -> 1.31 | H17: 0.004 | J17: 穿路箱涵 | K17: =C17 -> 1152 | L17: =ROUND(M17*1.3,2) -> 0.61 | M17: =M16 -> 0.47 | N17: =ROUND(L17/W17,2) -> 1.65 | O17: =ROUND(M17/V17,2) -> 1.57 | P17: =P16 -> 0.54 | Q17: =Q16 -> 0.46 | R17: 0.015 | S17: =H17 -> 0.004 | T17: ="1/"&ROUND(1/S17,0) -> 1/250 | U17: =U16 -> U80 | V17: =V16 -> 0.3 | W17: =W16 -> 0.37 | X17: =Y17-P17 -> 0.26 | Y17: =Y16 -> 0.8 | Z17: =E17 -> 1665.5 | AA17: =F17 -> 1664.19 | AB17: =AA17+Q17 -> 1664.65 | AD17: =Z17-AA17 -> 1.31
C18: 1162 | E18: =E17 -> 1665.5 | F18: =F17 -> 1664.19 | G18: =E18-F18 -> 1.31 | H18: 0.004 | K18: =C18 -> 1162 | L18: =ROUND(M18*1.3,2) -> 0.61 | M18: =M17 -> 0.47 | N18: =ROUND(L18/W18,2) -> 1.65 | O18: =ROUND(M18/V18,2) -> 1.57 | P18: =P17 -> 0.54 | Q18: =Q17 -> 0.46 | R18: 0.015 | S18: =H18 -> 0.004 | T18: ="1/"&ROUND(1/S18,0) -> 1/250 | U18: =U17 -> U80 | V18: =V17 -> 0.3 | W18: =W17 -> 0.37 | X18: =Y18-P18 -> 0.26 | Y18: =Y17 -> 0.8 | Z18: =E18 -> 1665.5 | AA18: =F18 -> 1664.19 | AB18: =AA18+Q18 -> 1664.65 | AD18: =Z18-AA18 -> 1.31
B19: K1+200 | C19: 1200 | D19: 1664.38 | E19: =ROUND(D19,2) -> 1664.38 | F19: =ROUND(F18-(C19-C18)*H18,2) -> 1664.04 | G19: =E19-F19 -> 0.34 | H19: 0.004 | J19: 1-1-2斗渠 | K19: =C19 -> 1200 | L19: =ROUND(M19*1.3,2) -> 0.61 | M19: =M18 -> 0.47 | N19: =ROUND(L19/W19,2) -> 1.65 | O19: =ROUND(M19/V19,2) -> 1.57 | P19: =P18 -> 0.54 | Q19: =Q18 -> 0.46 | R19: 0.015 | S19: =H19 -> 0.004 | T19: ="1/"&ROUND(1/S19,0) -> 1/250 | U19: =U18 -> U80 | V19: =V18 -> 0.3 | W19: =W18 -> 0.37 | X19: =Y19-P19 -> 0.26 | Y19: =Y18 -> 0.8 | Z19: =E19 -> 1664.38 | AA19: =F19 -> 1664.04 | AB19: =AA19+Q19 -> 1664.5 | AD19: =Z19-AA19 -> 0.34
B20: K1+300 | C20: 1300 | D20: 1664.086 | E20: =ROUND(D20,2) -> 1664.09 | F20: =ROUND(F19-(C20-C19)*H19,2) -> 1663.64 | G20: =E20-F20 -> 0.45 | H20: 0.004 | K20: =C20 -> 1300 | L20: =ROUND(M20*1.3,2) -> 0.61 | M20: =M19 -> 0.47 | N20: =ROUND(L20/W20,2) -> 1.65 | O20: =ROUND(M20/V20,2) -> 1.57 | P20: =P19 -> 0.54 | Q20: =Q19 -> 0.46 | R20: 0.015 | S20: =H20 -> 0.004 | T20: ="1/"&ROUND(1/S20,0) -> 1/250 | U20: =U19 -> U80 | V20: =V19 -> 0.3 | W20: =W19 -> 0.37 | X20: =Y20-P20 -> 0.26 | Y20: =Y19 -> 0.8 | Z20: =E20 -> 1664.09 | AA20: =F20 -> 1663.64 | AB20: =AA20+Q20 -> 1664.1 | AD20: =Z20-AA20 -> 0.45
B21: K1+400 | C21: 1400 | D21: 1663.567 | E21: =ROUND(D21,2) -> 1663.57 | F21: =ROUND(F20-(C21-C20)*H20,2) -> 1663.24 | G21: =E21-F21 -> 0.33 | H21: 0.004 | K21: =C21 -> 1400 | L21: =ROUND(M21*1.3,2) -> 0.61 | M21: =M20 -> 0.47 | N21: =ROUND(L21/W21,2) -> 1.65 | O21: =ROUND(M21/V21,2) -> 1.57 | P21: =P20 -> 0.54 | Q21: =Q20 -> 0.46 | R21: 0.015 | S21: =H21 -> 0.004 | T21: ="1/"&ROUND(1/S21,0) -> 1/250 | U21: =U20 -> U80 | V21: =V20 -> 0.3 | W21: =W20 -> 0.37 | X21: =Y21-P21 -> 0.26 | Y21: =Y20 -> 0.8 | Z21: =E21 -> 1663.57 | AA21: =F21 -> 1663.24 | AB21: =AA21+Q21 -> 1663.7 | AD21: =Z21-AA21 -> 0.33
B22: K1+500 | C22: 1500 | D22: 1663.093 | E22: =ROUND(D22,2) -> 1663.09 | F22: =ROUND(F21-(C22-C21)*0.0046,2) -> 1662.78 | G22: =E22-F22 -> 0.31 | H22: 0.004 | K22: =C22 -> 1500 | L22: =ROUND(M22*1.3,2) -> 0.61 | M22: =M21 -> 0.47 | N22: =ROUND(L22/W22,2) -> 1.65 | O22: =ROUND(M22/V22,2) -> 1.57 | P22: =P21 -> 0.54 | Q22: =Q21 -> 0.46 | R22: 0.015 | S22: =H22 -> 0.004 | T22: ="1/"&ROUND(1/S22,0) -> 1/250 | U22: =U21 -> U80 | V22: =V21 -> 0.3 | W22: =W21 -> 0.37 | X22: =Y22-P22 -> 0.26 | Y22: =Y21 -> 0.8 | Z22: =E22 -> 1663.09 | AA22: =F22 -> 1662.78 | AB22: =AA22+Q22 -> 1663.24 | AD22: =Z22-AA22 -> 0.31
B23: K1+600 | C23: 1600 | D23: 1662.406 | E23: =ROUND(D23,2) -> 1662.41 | F23: =ROUND(F22-(C23-C22)*0.0046,2) -> 1662.32 | G23: =E23-F23 -> 0.09 | H23: 0.004 | K23: =C23 -> 1600 | L23: =ROUND(M23*1.3,2) -> 0.61 | M23: =M22 -> 0.47 | N23: =ROUND(L23/W23,2) -> 1.65 | O23: =ROUND(M23/V23,2) -> 1.57 | P23: =P22 -> 0.54 | Q23: =Q22 -> 0.46 | R23: 0.015 | S23: =H23 -> 0.004 | T23: ="1/"&ROUND(1/S23,0) -> 1/250 | U23: =U22 -> U80 | V23: =V22 -> 0.3 | W23: =W22 -> 0.37 | X23: =Y23-P23 -> 0.26 | Y23: =Y22 -> 0.8 | Z23: =E23 -> 1662.41 | AA23: =F23 -> 1662.32 | AB23: =AA23+Q23 -> 1662.78 | AD23: =Z23-AA23 -> 0.09
B24: K1+700 | C24: 1700 | D24: 1662.157 | E24: =ROUND(D24,2) -> 1662.16 | F24: =ROUND(F23-(C24-C23)*0.0046,2) -> 1661.86 | G24: =E24-F24 -> 0.3 | H24: 0.004 | K24: =C24 -> 1700 | L24: =ROUND(M24*1.3,2) -> 0.61 | M24: =M23 -> 0.47 | N24: =ROUND(L24/W24,2) -> 1.65 | O24: =ROUND(M24/V24,2) -> 1.57 | P24: =P23 -> 0.54 | Q24: =Q23 -> 0.46 | R24: 0.015 | S24: =H24 -> 0.004 | T24: ="1/"&ROUND(1/S24,0) -> 1/250 | U24: =U23 -> U80 | V24: =V23 -> 0.3 | W24: =W23 -> 0.37 | X24: =Y24-P24 -> 0.26 | Y24: =Y23 -> 0.8 | Z24: =E24 -> 1662.16 | AA24: =F24 -> 1661.86 | AB24: =AA24+Q24 -> 1662.32 | AD24: =Z24-AA24 -> 0.3
B25: K1+800 | C25: 1800 | D25: 1661.687 | E25: =ROUND(D25,2) -> 1661.69 | F25: =ROUND(F24-(C25-C24)*0.0046,2) -> 1661.4 | G25: =E25-F25 -> 0.29 | H25: 0.004 | K25: =C25 -> 1800 | L25: =ROUND(M25*1.3,2) -> 0.61 | M25: =M24 -> 0.47 | N25: =ROUND(L25/W25,2) -> 1.65 | O25: =ROUND(M25/V25,2) -> 1.57 | P25: =P24 -> 0.54 | Q25: =Q24 -> 0.46 | R25: 0.015 | S25: =H25 -> 0.004 | T25: ="1/"&ROUND(1/S25,0) -> 1/250 | U25: =U24 -> U80 | V25: =V24 -> 0.3 | W25: =W24 -> 0.37 | X25: =Y25-P25 -> 0.26 | Y25: =Y24 -> 0.8 | Z25: =E25 -> 1661.69 | AA25: =F25 -> 1661.4 | AB25: =AA25+Q25 -> 1661.86 | AD25: =Z25-AA25 -> 0.29
B26: K1+900 | C26: 1900 | D26: 1661.154 | E26: =ROUND(D26,2) -> 1661.15 | F26: =ROUND(F25-(C26-C25)*0.0046,2) -> 1660.94 | G26: =E26-F26 -> 0.21 | H26: 0.004 | K26: =C26 -> 1900 | L26: =ROUND(M26*1.3,2) -> 0.61 | M26: =M25 -> 0.47 | N26: =ROUND(L26/W26,2) -> 1.65 | O26: =ROUND(M26/V26,2) -> 1.57 | P26: =P25 -> 0.54 | Q26: =Q25 -> 0.46 | R26: 0.015 | S26: =H26 -> 0.004 | T26: ="1/"&ROUND(1/S26,0) -> 1/250 | U26: =U25 -> U80 | V26: =V25 -> 0.3 | W26: =W25 -> 0.37 | X26: =Y26-P26 -> 0.26 | Y26: =Y25 -> 0.8 | Z26: =E26 -> 1661.15 | AA26: =F26 -> 1660.94 | AB26: =AA26+Q26 -> 1661.4 | AD26: =Z26-AA26 -> 0.21
B27: K2+000 | C27: 2000 | D27: 1660.534 | E27: =ROUND(D27,2) -> 1660.53 | F27: =ROUND(F26-(C27-C26)*0.0046,2) -> 1660.48 | G27: =E27-F27 -> 0.05 | H27: 0.004 | K27: =C27 -> 2000 | L27: =ROUND(M27*1.3,2) -> 0.61 | M27: =M26 -> 0.47 | N27: =ROUND(L27/W27,2) -> 1.65 | O27: =ROUND(M27/V27,2) -> 1.57 | P27: =P26 -> 0.54 | Q27: =Q26 -> 0.46 | R27: 0.015 | S27: =H27 -> 0.004 | T27: ="1/"&ROUND(1/S27,0) -> 1/250 | U27: =U26 -> U80 | V27: =V26 -> 0.3 | W27: =W26 -> 0.37 | X27: =Y27-P27 -> 0.26 | Y27: =Y26 -> 0.8 | Z27: =E27 -> 1660.53 | AA27: =F27 -> 1660.48 | AB27: =AA27+Q27 -> 1660.94 | AD27: =Z27-AA27 -> 0.05
B28: K2+100 | C28: 2100 | D28: 1660.105 | E28: =ROUND(D28,2) -> 1660.11 | F28: =ROUND(F27-(C28-C27)*0.0046,2) -> 1660.02 | G28: =E28-F28 -> 0.09 | H28: 0.004 | J28: 1-1-3斗渠 | K28: =C28 -> 2100 | L28: =ROUND(M28*1.3,2) -> 0.61 | M28: =M27 -> 0.47 | N28: =ROUND(L28/W28,2) -> 1.65 | O28: =ROUND(M28/V28,2) -> 1.57 | P28: =P27 -> 0.54 | Q28: =Q27 -> 0.46 | R28: 0.015 | S28: =H28 -> 0.004 | T28: ="1/"&ROUND(1/S28,0) -> 1/250 | U28: =U27 -> U80 | V28: =V27 -> 0.3 | W28: =W27 -> 0.37 | X28: =Y28-P28 -> 0.26 | Y28: =Y27 -> 0.8 | Z28: =E28 -> 1660.11 | AA28: =F28 -> 1660.02 | AB28: =AA28+Q28 -> 1660.48 | AD28: =Z28-AA28 -> 0.09
B29: K2+200 | C29: 2200 | D29: 1659.446 | E29: =ROUND(D29,2) -> 1659.45 | F29: =ROUND(F28-(C29-C28)*0.0046,2) -> 1659.56 | G29: =E29-F29 -> -0.11 | H29: 0.004 | K29: =C29 -> 2200 | L29: =ROUND(M29*1.3,2) -> 0.61 | M29: =M28 -> 0.47 | N29: =ROUND(L29/W29,2) -> 1.65 | O29: =ROUND(M29/V29,2) -> 1.57 | P29: =P28 -> 0.54 | Q29: =Q28 -> 0.46 | R29: 0.015 | S29: =H29 -> 0.004 | T29: ="1/"&ROUND(1/S29,0) -> 1/250 | U29: =U28 -> U80 | V29: =V28 -> 0.3 | W29: =W28 -> 0.37 | X29: =Y29-P29 -> 0.26 | Y29: =Y28 -> 0.8 | Z29: =E29 -> 1659.45 | AA29: =F29 -> 1659.56 | AB29: =AA29+Q29 -> 1660.02 | AD29: =Z29-AA29 -> -0.11
B30: K2+300 | C30: 2300 | D30: 1658.885 | E30: =ROUND(D30,2) -> 1658.89 | F30: =ROUND(F29-(C30-C29)*0.0046,2) -> 1659.1 | G30: =E30-F30 -> -0.21 | H30: 0.004 | K30: =C30 -> 2300 | L30: =ROUND(M30*1.3,2) -> 0.61 | M30: =M29 -> 0.47 | N30: =ROUND(L30/W30,2) -> 1.65 | O30: =ROUND(M30/V30,2) -> 1.57 | P30: =P29 -> 0.54 | Q30: =Q29 -> 0.46 | R30: 0.015 | S30: =H30 -> 0.004 | T30: ="1/"&ROUND(1/S30,0) -> 1/250 | U30: =U29 -> U80 | V30: =V29 -> 0.3 | W30: =W29 -> 0.37 | X30: =Y30-P30 -> 0.26 | Y30: =Y29 -> 0.8 | Z30: =E30 -> 1658.89 | AA30: =F30 -> 1659.1 | AB30: =AA30+Q30 -> 1659.56 | AD30: =Z30-AA30 -> -0.21
B31: K2+400 | C31: 2400 | D31: 1658.81 | E31: =ROUND(D31,2) -> 1658.81 | F31: =ROUND(F30-(C31-C30)*0.0046,2) -> 1658.64 | G31: =E31-F31 -> 0.17 | H31: 0.004 | I31: =F21-F31 -> 4.6 | K31: =C31 -> 2400 | L31: =ROUND(M31*1.3,2) -> 0.61 | M31: =M30 -> 0.47 | N31: =ROUND(L31/W31,2) -> 1.65 | O31: =ROUND(M31/V31,2) -> 1.57 | P31: =P30 -> 0.54 | Q31: =Q30 -> 0.46 | R31: 0.015 | S31: =H31 -> 0.004 | T31: ="1/"&ROUND(1/S31,0) -> 1/250 | U31: =U30 -> U80 | V31: =V30 -> 0.3 | W31: =W30 -> 0.37 | X31: =Y31-P31 -> 0.26 | Y31: =Y30 -> 0.8 | Z31: =E31 -> 1658.81 | AA31: =F31 -> 1658.64 | AB31: =AA31+Q31 -> 1659.1 | AD31: =Z31-AA31 -> 0.17
B32: K2+500 | C32: 2500 | D32: 1658.617 | E32: =ROUND(D32,2) -> 1658.62 | F32: =ROUND(F31-(C32-C31)*H31,2) -> 1658.24 | G32: =E32-F32 -> 0.38 | H32: 0.004 | I32: =I31/(C31-C21) -> 0.0046 | K32: =C32 -> 2500 | L32: =ROUND(M32*1.3,2) -> 0.61 | M32: =M31 -> 0.47 | N32: =ROUND(L32/W32,2) -> 1.65 | O32: =ROUND(M32/V32,2) -> 1.57 | P32: =P31 -> 0.54 | Q32: =Q31 -> 0.46 | R32: 0.015 | S32: =H32 -> 0.004 | T32: ="1/"&ROUND(1/S32,0) -> 1/250 | U32: =U31 -> U80 | V32: =V31 -> 0.3 | W32: =W31 -> 0.37 | X32: =Y32-P32 -> 0.26 | Y32: =Y31 -> 0.8 | Z32: =E32 -> 1658.62 | AA32: =F32 -> 1658.24 | AB32: =AA32+Q32 -> 1658.7 | AD32: =Z32-AA32 -> 0.38
B33: K2+600 | C33: 2600 | D33: 1658.042 | E33: =ROUND(D33,2) -> 1658.04 | F33: =ROUND(F32-(C33-C32)*H32,2) -> 1657.84 | G33: =E33-F33 -> 0.2 | H33: 0.004 | K33: =C33 -> 2600 | L33: =ROUND(M33*1.3,2) -> 0.61 | M33: =M32 -> 0.47 | N33: =ROUND(L33/W33,2) -> 1.65 | O33: =ROUND(M33/V33,2) -> 1.57 | P33: =P32 -> 0.54 | Q33: =Q32 -> 0.46 | R33: 0.015 | S33: =H33 -> 0.004 | T33: ="1/"&ROUND(1/S33,0) -> 1/250 | U33: =U32 -> U80 | V33: =V32 -> 0.3 | W33: =W32 -> 0.37 | X33: =Y33-P33 -> 0.26 | Y33: =Y32 -> 0.8 | Z33: =E33 -> 1658.04 | AA33: =F33 -> 1657.84 | AB33: =AA33+Q33 -> 1658.3 | AD33: =Z33-AA33 -> 0.2
B34: K2+700 | C34: 2700 | D34: 1657.766 | E34: =ROUND(D34,2) -> 1657.77 | F34: =ROUND(F33-(C34-C33)*H33,2) -> 1657.44 | G34: =E34-F34 -> 0.33 | H34: 0.004 | J34: 1-1-4斗渠 | K34: =C34 -> 2700 | L34: =ROUND(M34*1.3,2) -> 0.61 | M34: =M33 -> 0.47 | N34: =ROUND(L34/W34,2) -> 1.65 | O34: =ROUND(M34/V34,2) -> 1.57 | P34: =P33 -> 0.54 | Q34: =Q33 -> 0.46 | R34: 0.015 | S34: =H34 -> 0.004 | T34: ="1/"&ROUND(1/S34,0) -> 1/250 | U34: =U33 -> U80 | V34: =V33 -> 0.3 | W34: =W33 -> 0.37 | X34: =Y34-P34 -> 0.26 | Y34: =Y33 -> 0.8 | Z34: =E34 -> 1657.77 | AA34: =F34 -> 1657.44 | AB34: =AA34+Q34 -> 1657.9 | AD34: =Z34-AA34 -> 0.33
